Workbook

Sheet 상품별심사처리기준
A1: 구분 | C1: 처리정보명 | D1: 전문번호 | E1: 전문내용 | F1: R-Clips 전문구성 | I1: 관련테이블 | J1: 비고
F2: 이지론 (신용회원) | G2: 이지론플러스 (체크회원) | H2: 일사천리론 (비회원)
A3: 대내 | B3: 심사 대상 정보 (분석계) | C3: 심사 사전 대상자 정보 | D3: n/a | E3: 사전대상자 선정 시점 정보 | F3: 통합 | H3: 미사용 | I3: [1] GEA신용회원사전대상자내역 [2] GEA체크회원사전대상자내역 | J3: 1) 수신 데이터 적재 - 수신 후 해당 테이블을 매월 25일 경에 Batch로 적재한다.
B4: 심사 내부 정보 (처리계) | C4: 심사 사전 처리계 정보 | D4: n/a | E4: 신청 시점 처리계 내부정보 | F4: 통합 | I4: [1] GEA심사사전정보내역 [2] GEA심사사전부적격결과내역 | J4: 1) 심사시점에 처리계 테이블을 실시간 참조하여 해당 테이블에 적재하고, RCLIPS I/F시 사용한다.
A5: 대외 | B5: NICE 대외 신용 정보 | C5: 개인 신용정보 | D5: 1F003 | E5: 개인연체정보 + 신용요약정보 + 개인신용평점 | F5: 통합 | H5: 개별 | I5: [1] GEA_NICE신용정보전문 [2] GEA_NICE신용평점정보상세전문 [3] GEA_NICE신용요약정보상세전문 [4] GEA_NICE신용특별요약정보상세전문 | J5: 1) 송신전문 관리 - 송신한 전문에 대하여는 관리하지 않음 (유지수D 요청 사항) 2) 수신전문 관리 - 수신된 전문은 당사의 심사전략솔루션(RCLIPS)에서 사용시 편의성을 위하여 데이터 Parsing을 하여 테이블에 항목별로 적재한다. - 당일 동일 I/F발생시 추가적인 I/F는 수행하지 않고 해당 수신적재된 건을 이용한다.
C6: 실시간동시대출 | D6: 13003 | E6: 실시간 동시대출 정보 | F6: 통합 | I6: [1] GEA_NICE동시대출전문 [2] GEA_NICE동시대출상세전문
C7: 사기거래허위적발 (FRAUD) | D7: 2A116 | E7: 사기거래적발 | F7: 통합 | H7: 미사용 | I7: [1] GEA_NICE허위대출전문 [2] GEA_NICE허위대출스코어상세전문 [3] GEA_NICE허위대출규칙정보상세전문
B8: KCB 대외 신용 정보 | C8: 개인 신용정보 | D8: 0400-437/0410-437 | E8: 개인신용평점 + 신용요약정보 | F8: 통합 | H8: 개별 | I8: [1] GEA_KCB신용정보전문 [2] GEA_KCB신용평점정보상세전문 [3] GEA_KCB신용요약정보상세전문
C9: 실시간동시대출 | D9: 0400-482/0410-482 | E9: 실시간 동시대출 정보 | F9: 통합 | I9: [1] GEA_KCB동시대출전문 [2] GEA_KCB동시대출상세전문
C10: 사기거래허위적발 (FRAUD) | D10: 0200-231/0210-231 | E10: 사기거래적발 | F10: 통합 | H10: 미사용 | I10: [1] GEA_KCB허위대출전문 [2] GEA_KCB허위대출결과상세전문
A12: < 시트 설명 >
A13: Sheet 명 | D13: 정리
A14: 심사테이블 | D14: 심사 프로세스에서 대내(분석계,처리계) 및 대외(NICE, KCB) 의 정보를 참조하거나 I/F등을 통하여 실제 적재 및 관리하는 테이블 레이아아웃
A15: RCLIPS송신(이지론) | D15: 신용회원대출(이지론) 심사에서 관리하는 각 테이블로부터 심사전략솔루션(RCLIPS)의 입력항목 레이아웃과 각 항목별 원천항목(SOURCE COLUMN)별 Maping Rule
A16: RCLIPS수신(이지론) | D16: 신용회원대출(이지론) 심사에 대하여 심사전략솔루션(RCLIPS)로부터 수신받은 심사결과 항목이다.
A17: RCLIPS송신(이지론플러스&일사천리론) | D17: 체크회원(이지론플러스) 및 비회원대출(일사천리론) 심사에서 관리하는 각 테이블로부터 심사전략솔루션(RCLIPS)의 입력항목 레이아웃과 각 항목별 원천항목(SOURCE COLUMN)별 Maping Rule
A18: RCLIPS수신(이지론플러스&일사천리론) | D18: 체크회원(이지론플러스) 및 비회원대출(일사천리론) 심사에 대하여 심사전략솔루션(RCLIPS)로부터 수신받은 심사결과 항목이다.
A19: 참고_AsIs_RCLIPS송신 | D19: As-Is의 RCLIPS를 이용하여 심사를 하였던 일사천리론에 대한 RCLIPS 송신시 입력항목 레이아웃이다.
A20: 참고_AsIs_RCLIPS수신 | D20: As-Is의 RCLIPS를 이용하여 심사를 하였던 일사천리론에 대한 RCLIPS 수신시 입력항목 레이아웃이다.
A21: 용어신청대상 | D21: 심사 관련 테이블 추가시 반영요청 될 항목이다.
A23: < 연관 파일 설명 >
A24: 파일 명 | C24: 구분 | D24: 처리정보명 | E24: 주요내용
A25: 01-1. 사전대상자정보.xlsx | C25: 심사 대상 정보 (분석계) | E25: 분석계로부터 수신받은 대상자(신용회원/체크회원)
A26: 02-2. 내부정보.xlsx | C26: 심사 내부 정보 (처리계) | E26: 처리계 원장으로 부터 심사시 참조하는 각종 항목 및 해당 항목 추출기준
A27: 03-1. NICE_신용정보.xlsx | C27: NICE 대외 신용 정보 | D27: 개인 신용정보 | E27: 대외신용정보 중 NICE의 개인 신용정보 조회 I/F에 대한 입출력 항목 및 RCLIPS에서 사용할 각 종 항목에 대한LIST
A28: 03-2. KCB_신용정보.xlsx | C28: KCB 대외 신용 정보 | D28: 개인 신용정보 | E28: 대외신용정보 중 KCB의 개인 신용정보 조회 I/F에 대한 입출력 항목 및 RCLIPS에서 사용할 각 종 항목에 대한LIST
A29: 03-3. NICE_동시대출.xlsx | C29: NICE 대외 신용 정보 | D29: 실시간동시대출 | E29: 대외신용정보 중 NICE의 실시간 동시대출체크 조회 I/F에 대한 입출력 항목 및 RCLIPS에서 사용할 각 종 항목에 대한LIST
A30: 03-4. KCB_동시대출.xlsx | C30: KCB 대외 신용 정보 | D30: 실시간동시대출 | E30: 대외신용정보 중 KCB의 실시간 동시대출체크 조회 I/F에 대한 입출력 항목 및 RCLIPS에서 사용할 각 종 항목에 대한LIST
A31: 03-5. NICE_FRAUD.xlsx | C31: NICE 대외 신용 정보 | D31: 사기거래허위적발 (FRAUD) | E31: 대외신용정보 중 NICE의 사기거래허위적발 (FRAUD)조회 I/F에 대한 입출력 항목 및 RCLIPS에서 사용할 각 종 항목에 대한LIST
A32: 03-6. KCB_FRAUD.xlsx | C32: KCB 대외 신용 정보 | D32: 사기거래허위적발 (FRAUD) | E32: 대외신용정보 중 KCB의 사기거래허위적발 (FRAUD)조회 I/F에 대한 입출력 항목 및 RCLIPS에서 사용할 각 종 항목에 대한LIST

Sheet 심사테이블
A1: To-Be 테이블 및 항목 | O1: 검토 확인 (원천)
A2: NO | C2: 테이블명 | D2: 테이블한글명 | E2: 컬럼명 | F2: 컬럼한글명 (TO-BE명) | G2: PK 여부 | H2: NULL 여부 | I2: 타입 | J2: 길이 | K2: 소수점 | L2: 테이블 반영분류 | M2: 메타신규대상 | N2: 비고 | O2: 테이블 | P2: 형식 | Q2: 길이 | R2: 항목명 | S2: 이지론 | T2: 이지론 플러스 | U2: 일사 천리
A3: 1 | B3: 1) 심사 대상 정보 (분석계) | C3: TBGEAA209 | D3: GEA신용회원사전대상자내역 | E3: 적용시작일자 | F3: 심사대상적용시작년월일 | G3: Y | H3: N | I3: VARCHAR2 | J3: 8 | L3: 확인중 | S3: ○
A4: =IF(D3=D4,A3+1,1) -> 2 | B4: 1) 심사 대상 정보 (분석계) | C4: TBGEAA209 | D4: GEA신용회원사전대상자내역 | E4: 고객식별자 | F4: 고객식별자 | G4: Y | H4: N | I4: VARCHAR2 | J4: 10 | L4: 확인중 | S4: ○
A5: =IF(D4=D5,A4+1,1) -> 3 | B5: 1) 심사 대상 정보 (분석계) | C5: TBGEAA209 | D5: GEA신용회원사전대상자내역 | E5: 고객관리번호 | F5: 고객관리번호 | G5: Y | H5: N | I5: VARCHAR2 | J5: 5 | L5: 확인중 | S5: ○
A6: =IF(D5=D6,A5+1,1) -> 4 | B6: 1) 심사 대상 정보 (분석계) | C6: TBGEAA209 | D6: GEA신용회원사전대상자내역 | E6: 적용종료일자 | F6: 심사대상적용종료년월일 | I6: VARCHAR2 | J6: 8 | L6: 확인중 | S6: ○
A7: =IF(D6=D7,A6+1,1) -> 5 | B7: 1) 심사 대상 정보 (분석계) | C7: TBGEAA209 | D7: GEA신용회원사전대상자내역 | E7: 이지론탈락사유 | F7: 이지론탈락사유 | I7: VARCHAR2 | J7: 60 | L7: 확인중 | O7: TSMADLN19 | P7: String | Q7: 60 | R7: 이지론탈락사유내용 | S7: ○
A8: =IF(D7=D8,A7+1,1) -> 6 | B8: 1) 심사 대상 정보 (분석계) | C8: TBGEAA209 | D8: GEA신용회원사전대상자내역 | E8: 우량고객내용 | F8: 이지누리론대상편성사유 | I8: VARCHAR2 | J8: 60 | L8: 확인중 | O8: TSMADLN19 | P8: String | Q8: 60 | R8: 우량고객내용 | S8: ○
A9: =IF(D8=D9,A8+1,1) -> 7 | B9: 1) 심사 대상 정보 (분석계) | C9: TBGEAA209 | D9: GEA신용회원사전대상자내역 | E9: 카드최초가입년월일 | F9: 카드최초가입년월일 | I9: VARCHAR2 | J9: 8 | L9: 확인중 | O9: TSMADLN19 | P9: String | Q9: 8 | R9: 최초가입년월일 | S9: ○
A10: =IF(D9=D10,A9+1,1) -> 8 | B10: 1) 심사 대상 정보 (분석계) | C10: TBGEAA209 | D10: GEA신용회원사전대상자내역 | E10: CB신용등급코드 | F10: CB신용등급코드 | I10: VARCHAR2 | J10: 4 | L10: 확인중 | O10: TSMADLN19 | P10: String | Q10: 4 | R10: CB신용등급코드 | S10: ○
A11: =IF(D10=D11,A10+1,1) -> 9 | B11: 1) 심사 대상 정보 (분석계) | C11: TBGEAA209 | D11: GEA신용회원사전대상자내역 | E11: PD등급내용 | F11: PD등급내용 | I11: VARCHAR2 | J11: 5 | L11: 확인중 | O11: TSMADLN19 | P11: String | Q11: 5 | R11: 카드론PD구분 | S11: ○
A12: =IF(D11=D12,A11+1,1) -> 10 | B12: 1) 심사 대상 정보 (분석계) | C12: TBGEAA209 | D12: GEA신용회원사전대상자내역 | E12: 이지론한도금액 | F12: 이지론한도금액 | H12: N | I12: NUMBER | J12: 15 | L12: 확인중 | O12: TSMADLN19 | P12: Numeric | Q12: 15 | R12: 이지론한도 | S12: ○
A13: =IF(D12=D13,A12+1,1) -> 11 | B13: 1) 심사 대상 정보 (분석계) | C13: TBGEAA209 | D13: GEA신용회원사전대상자내역 | E13: 이지론대출금리 | F13: 이지론대출금리 | H13: N | I13: NUMBER | J13: 9 | K13: 5 | L13: 확인중 | O13: TSMADLN19 | P13: Numeric | Q13: 9.5 | R13: 대출이율 | S13: ○
A14: =IF(D13=D14,A13+1,1) -> 12 | B14: 1) 심사 대상 정보 (분석계) | C14: TBGEAA209 | D14: GEA신용회원사전대상자내역 | E14: 연간원리금상환금액 | F14: 연간원리금상환금액 | H14: N | I14: NUMBER | J14: 15 | L14: 확인중 | O14: TSMADLN19 | P14: Numeric | Q14: 15 | R14: 연원리금상환금액 | S14: ○
A15: =IF(D14=D15,A14+1,1) -> 13 | B15: 1) 심사 대상 정보 (분석계) | C15: TBGEAA209 | D15: GEA신용회원사전대상자내역 | E15: 유효가맹점여부 | F15: 유효가맹점여부 | I15: VARCHAR2 | J15: 1 | L15: 확인중 | O15: TSMADLA19 | P15: String | Q15: 1 | R15: 유효가맹점여부 | S15: ○
A16: =IF(D15=D16,A15+1,1) -> 14 | B16: 1) 심사 대상 정보 (분석계) | C16: TBGEAA209 | D16: GEA신용회원사전대상자내역 | E16: 유효사업자여부 | F16: 유효사업자여부 | I16: VARCHAR2 | J16: 1 | L16: 확인중 | O16: TSMADLA19 | P16: String | Q16: 1 | R16: 유효사업자여부 | S16: ○
A17: =IF(D16=D17,A16+1,1) -> 15 | B17: 1) 심사 대상 정보 (분석계) | C17: TBGEAA209 | D17: GEA신용회원사전대상자내역 | E17: 론니즈등급구분코드 | F17: 카드론니즈등급구분코드 | I17: VARCHAR2 | J17: 2 | L17: 확인중 | O17: TSMADLN19 | P17: String | Q17: 2 | R17: 론니즈등급구분 | S17: ○
A18: =IF(D17=D18,A17+1,1) -> 16 | B18: 1) 심사 대상 정보 (분석계) | C18: TBGEAA209 | D18: GEA신용회원사전대상자내역 | E18: 신용등급코드 | F18: 신용등급코드 | I18: VARCHAR2 | J18: 4 | L18: 확인중 | O18: TSMADLN19 | P18: String | Q18: 4 | R18: 신용등급코드 | S18: ○
A19: =IF(D18=D19,A18+1,1) -> 17 | B19: 1) 심사 대상 정보 (분석계) | C19: TBGEAA209 | D19: GEA신용회원사전대상자내역 | E19: KCB신용평가점수내용 | F19: KCB신용평가점수내용 | H19: N | I19: NUMBER | J19: 4 | L19: 확인중 | O19: TSMADLN19 | P19: Numeric | Q19: 4 | R19: 신용평점일련번호 | S19: ○
A20: =IF(D19=D20,A19+1,1) -> 18 | B20: 1) 심사 대상 정보 (분석계) | C20: TBGEAA209 | D20: GEA신용회원사전대상자내역 | E20: 최근3개월채권잔액 | F20: 최근3개월채권평잔 | H20: N | I20: NUMBER | J20: 15 | L20: 확인중 | O20: TSMADLN19 | P20: Numeric | Q20: 15 | R20: 최근3개월카드채권평잔 | S20: ○
A21: =IF(D20=D21,A20+1,1) -> 19 | B21: 1) 심사 대상 정보 (분석계) | C21: TBGEAA209 | D21: GEA신용회원사전대상자내역 | E21: 신규고객여부 | F21: 신규카드발급2개월초과여부 | I21: VARCHAR2 | J21: 1 | L21: 확인중 | O21: TSMADLN19 | P21: String | Q21: 1 | R21: 신규기존여부 | S21: ○
A22: =IF(D21=D22,A21+1,1) -> 20 | B22: 1) 심사 대상 정보 (분석계) | C22: TBGEAA209 | D22: GEA신용회원사전대상자내역 | E22: 최근12개월카드론평잔 | F22: 최근12개월카드론평잔 | H22: N | I22: NUMBER | J22: 15 | L22: 확인중 | O22: TSMADLN19 | P22: Numeric | Q22: 15 | R22: 최근12개월카드론평잔 | S22: ○
A23: =IF(D22=D23,A22+1,1) -> 21 | B23: 1) 심사 대상 정보 (분석계) | C23: TBGEAA209 | D23: GEA신용회원사전대상자내역 | E23: 월가처분소득금액 | F23: 월가처분소득금액 | H23: N | I23: NUMBER | J23: 15 | L23: 확인중 | O23: TSMADLN19 | P23: Numeric | Q23: 15 | R23: 월가처분소득금액 | S23: ○
A24: =IF(D23=D24,A23+1,1) -> 22 | B24: 1) 심사 대상 정보 (분석계) | C24: TBGEAA209 | D24: GEA신용회원사전대상자내역 | E24: 등급별최대한도금액 | F24: 결합등급한도금액 | H24: N | I24: NUMBER | J24: 15 | L24: 확인중 | O24: TSMADLN19 | P24: Numeric | Q24: 15 | R24: 등급별최고한도 | S24: ○
A25: =IF(D24=D25,A24+1,1) -> 23 | B25: 1) 심사 대상 정보 (분석계) | C25: TBGEAA209 | D25: GEA신용회원사전대상자내역 | E25: 연령한도제한금액 | F25: 연령한도제한금액 | H25: N | I25: NUMBER | J25: 15 | L25: 확인중 | O25: TSMADLN19 | P25: Numeric | Q25: 15 | R25: 연령별한도 | S25: ○
A26: =IF(D25=D26,A25+1,1) -> 24 | B26: 1) 심사 대상 정보 (분석계) | C26: TBGEAA209 | D26: GEA신용회원사전대상자내역 | E26: 이용가능한도미사용금액 | F26: 이용가능한도미사용금액 | H26: N | I26: NUMBER | J26: 15 | L26: 확인중 | O26: TSMADLN19 | P26: Numeric | Q26: 15 | R26: 이용가능한도미사용금액 | S26: ○
A27: =IF(D26=D27,A26+1,1) -> 25 | B27: 1) 심사 대상 정보 (분석계) | C27: TBGEAA209 | D27: GEA신용회원사전대상자내역 | E27: CSM연소득금액 | F27: CSM연소득금액 | H27: N | I27: NUMBER | J27: 15 | L27: 확인중 | O27: TSMADLN19 | P27: Numeric | Q27: 15 | R27: CSM연소득금액 | S27: ○
A28: =IF(D27=D28,A27+1,1) -> 26 | B28: 1) 심사 대상 정보 (분석계) | C28: TBGEAA209 | D28: GEA신용회원사전대상자내역 | E28: 만기일시한도금액 | F28: 이지론일시상환한도금액 | H28: N | I28: NUMBER | J28: 15 | L28: 확인중 | O28: TSMADLN19 | P28: Numeric | Q28: 15 | R28: 만기일시한도 | S28: ○
A29: =IF(D28=D29,A28+1,1) -> 27 | B29: 1) 심사 대상 정보 (분석계) | C29: TBGEAA209 | D29: GEA신용회원사전대상자내역 | E29: 낙아웃구제대상여부 | F29: 이지누리론낙아웃구제대상여부 | I29: VARCHAR2 | J29: 1 | L29: 확인중 | O29: TSMADLN19 | P29: String | Q29: 1 | R29: 구제대상여부 | S29: ○
A30: =IF(D29=D30,A29+1,1) -> 28 | B30: 1) 심사 대상 정보 (분석계) | C30: TBGEAA209 | D30: GEA신용회원사전대상자내역 | E30: 이지론소액한도대상여부 | F30: 이지누리론소액한도대상여부 | I30: VARCHAR2 | J30: 1 | L30: 확인중 | O30: TSMADLN19 | P30: String | Q30: 1 | R30: 소액한도대상여부 | S30: ○
A31: =IF(D30=D31,A30+1,1) -> 29 | B31: 1) 심사 대상 정보 (분석계) | C31: TBGEAA209 | D31: GEA신용회원사전대상자내역 | E31: 이지론최장거치개월수 | F31: 이지론거치기간수 | H31: N | I31: NUMBER | J31: 5 | L31: 확인중 | O31: TSMADLN19 | P31: Numeric | Q31: 5 | R31: 최장거치개월수 | S31: ○
A32: =IF(D31=D32,A31+1,1) -> 30 | B32: 1) 심사 대상 정보 (분석계) | C32: TBGEAA209 | D32: GEA신용회원사전대상자내역 | E32: 이지론최장대출기간월수 | F32: 이지론분할상환대출기간수 | H32: N | I32: NUMBER | J32: 5 | L32: 확인중 | O32: TSMADLN19 | P32: Numeric | Q32: 5 | R32: 최장대출기간월수 | S32: ○
A33: =IF(D32=D33,A32+1,1) -> 31 | B33: 1) 심사 대상 정보 (분석계) | C33: TBGEAA209 | D33: GEA신용회원사전대상자내역 | E33: 일반대출인정기준년월 | F33: 이지론플러스대출자격유효년월 | I33: VARCHAR2 | J33: 6 | L33: 확인중 | O33: TSMADLN19 | P33: String | Q33: 6 | R33: 일반대출인정기준년월 | S33: ○
A34: =IF(D33=D34,A33+1,1) -> 32 | B34: 1) 심사 대상 정보 (분석계) | C34: TBGEAA209 | D34: GEA신용회원사전대상자내역 | E34: 일반대출인정금액 | F34: 이지론플러스이전한도금액 | H34: N | I34: NUMBER | J34: 15 | L34: 확인중 | O34: TSMADLN19 | P34: Numeric | Q34: 15 | R34: 일반대출인정금액 | S34: ○
A35: =IF(D34=D35,A34+1,1) -> 33 | B35: 1) 심사 대상 정보 (분석계) | C35: TBGEAA209 | D35: GEA신용회원사전대상자내역 | E35: TM적용한도금액 | F35: 이지론증액한도금액 | H35: N | I35: NUMBER | J35: 15 | L35: 확인중 | O35: TSMADLN19 | P35: Numeric | Q35: 15 | R35: TM적용한도 | S35: ○
A36: =IF(D35=D36,A35+1,1) -> 34 | B36: 1) 심사 대상 정보 (분석계) | C36: TBGEAA209 | D36: GEA신용회원사전대상자내역 | E36: 신용BSS산정대상구분코드 | F36: 신용BSS산정대상구분코드 | I36: VARCHAR2 | J36: 3 | L36: 확인중 | O36: TSMADLN19 | P36: String | Q36: 3 | R36: 신용BSS산정대상구분 | S36: ○
A37: =IF(D36=D37,A36+1,1) -> 35 | B37: 1) 심사 대상 정보 (분석계) | C37: TBGEAA209 | D37: GEA신용회원사전대상자내역 | E37: 통합카드BSS모형구분코드 | F37: 통합카드BSS모형구분코드 | I37: VARCHAR2 | J37: 2 | L37: 확인중 | O37: TSMADLN19 | P37: String | Q37: 2 | R37: 신용BSS모형구분 | S37: ○
A38: =IF(D37=D38,A37+1,1) -> 36 | B38: 1) 심사 대상 정보 (분석계) | C38: TBGEAA209 | D38: GEA신용회원사전대상자내역 | E38: 신용카드BSS평가점수 | F38: 신용카드BSS평가점수 | H38: N | I38: NUMBER | J38: 5 | L38: 확인중 | O38: TSMADLN19 | P38: Numeric | Q38: 5 | R38: 신용BSS평점 | S38: ○
A39: =IF(D38=D39,A38+1,1) -> 37 | B39: 1) 심사 대상 정보 (분석계) | C39: TBGEAA209 | D39: GEA신용회원사전대상자내역 | E39: 신용BSS등급구분코드 | F39: 신용BSS등급구분코드 | I39: VARCHAR2 | J39: 2 | L39: 확인중 | O39: TSMADLN19 | P39: String | Q39: 2 | R39: 신용BSS등급 | S39: ○
A40: =IF(D39=D40,A39+1,1) -> 38 | B40: 1) 심사 대상 정보 (분석계) | C40: TBGEAA209 | D40: GEA신용회원사전대상자내역 | E40: 카드론신규모형구분코드 | F40: 카드론신규모형구분코드 | I40: VARCHAR2 | J40: 2 | L40: 확인중 | O40: TSMADLN19 | P40: String | Q40: 2 | R40: 카드론신규모형구분 | S40: ○
...

Sheet DW수보테이블
A1: To-Be 테이블 및 항목 | O1: 검토 확인 (원천)
A2: NO | C2: 테이블명 | D2: 테이블한글명 | E2: 컬럼명 | F2: 컬럼한글명 (TO-BE명) | G2: PK 여부 | H2: NULL 여부 | I2: 타입 | J2: 길이 | K2: 소수점 | L2: 테이블 반영분류 | M2: 메타신규대상 | N2: 비고 | O2: 테이블 | P2: 형식 | Q2: 길이 | R2: 항목명 | S2: 이지론 | T2: 이지론 플러스 | U2: 일사 천리 | W2: 테이블 | X2: 필드수
A3: 1 | B3: 1) 심사 대상 정보 (분석계) | C3: TBGEAA209 | D3: GEA신용회원사전대상자내역 | E3: 적용시작일자 | F3: 심사대상적용시작년월일 | G3: Y | H3: N | I3: VARCHAR2 | J3: 8 | L3: 확인중 | S3: ○ | W3: TSMADLN19 | X3: =COUNTIF(O:O,W3) -> 105
A4: =IF(D3=D4,A3+1,1) -> 2 | B4: 1) 심사 대상 정보 (분석계) | C4: TBGEAA209 | D4: GEA신용회원사전대상자내역 | E4: 고객식별자 | F4: 고객식별자 | G4: Y | H4: N | I4: VARCHAR2 | J4: 10 | L4: 확인중 | O4: TSMADLN19 | P4: String | Q4: 10 | R4: 고객식별자 | S4: ○ | W4: TSMADLA19 | X4: =COUNTIF(O:O,W4) -> 15
A5: =IF(D4=D5,A4+1,1) -> 3 | B5: 1) 심사 대상 정보 (분석계) | C5: TBGEAA209 | D5: GEA신용회원사전대상자내역 | E5: 고객관리번호 | F5: 고객관리번호 | G5: Y | H5: N | I5: VARCHAR2 | J5: 5 | L5: 확인중 | O5: TSMADLN19 | P5: String | Q5: 5 | R5: 고객관리번호 | S5: ○ | W5: TSMADLG19 | X5: =COUNTIF(O:O,W5) -> 8
A6: =IF(D5=D6,A5+1,1) -> 4 | B6: 1) 심사 대상 정보 (분석계) | C6: TBGEAA209 | D6: GEA신용회원사전대상자내역 | E6: 적용종료일자 | F6: 심사대상적용종료년월일 | I6: VARCHAR2 | J6: 8 | L6: 확인중 | S6: ○ | W6: TSMADLNM1 | X6: =COUNTIF(O:O,W6) -> 5
A7: =IF(D6=D7,A6+1,1) -> 5 | B7: 1) 심사 대상 정보 (분석계) | C7: TBGEAA209 | D7: GEA신용회원사전대상자내역 | E7: 이지론탈락사유 | F7: 이지론탈락사유 | I7: VARCHAR2 | J7: 60 | L7: 확인중 | O7: TSMADLN19 | P7: String | Q7: 60 | R7: 이지론탈락사유내용 | S7: ○ | W7: TSMADLNM2 | X7: =COUNTIF(O:O,W7) -> 5
A8: =IF(D7=D8,A7+1,1) -> 6 | B8: 1) 심사 대상 정보 (분석계) | C8: TBGEAA209 | D8: GEA신용회원사전대상자내역 | E8: 우량고객내용 | F8: 이지누리론대상편성사유 | I8: VARCHAR2 | J8: 60 | L8: 확인중 | O8: TSMADLN19 | P8: String | Q8: 60 | R8: 우량고객내용 | S8: ○ | W8: TSMADLNM3 | X8: =COUNTIF(O:O,W8) -> 12
A9: =IF(D8=D9,A8+1,1) -> 7 | B9: 1) 심사 대상 정보 (분석계) | C9: TBGEAA209 | D9: GEA신용회원사전대상자내역 | E9: 카드최초가입년월일 | F9: 카드최초가입년월일 | I9: VARCHAR2 | J9: 8 | L9: 확인중 | O9: TSMADLN19 | P9: String | Q9: 8 | R9: 최초가입년월일 | S9: ○ | W9: TSMADLF19 | X9: =COUNTIF(O:O,W9) -> 4
A10: =IF(D9=D10,A9+1,1) -> 8 | B10: 1) 심사 대상 정보 (분석계) | C10: TBGEAA209 | D10: GEA신용회원사전대상자내역 | E10: CB신용등급코드 | F10: CB신용등급코드 | I10: VARCHAR2 | J10: 4 | L10: 확인중 | O10: TSMADLN19 | P10: String | Q10: 4 | R10: CB신용등급코드 | S10: ○ | W10: TSMADLC19 | X10: =COUNTIF(O:O,W10) -> 151
A11: =IF(D10=D11,A10+1,1) -> 9 | B11: 1) 심사 대상 정보 (분석계) | C11: TBGEAA209 | D11: GEA신용회원사전대상자내역 | E11: PD등급내용 | F11: PD등급내용 | I11: VARCHAR2 | J11: 5 | L11: 확인중 | O11: TSMADLN19 | P11: String | Q11: 5 | R11: 카드론PD구분 | S11: ○ | X11: =COUNTIF($O$3:$O$317,"") -> 10
A12: =IF(D11=D12,A11+1,1) -> 10 | B12: 1) 심사 대상 정보 (분석계) | C12: TBGEAA209 | D12: GEA신용회원사전대상자내역 | E12: 이지론한도금액 | F12: 이지론한도금액 | H12: N | I12: NUMBER | J12: 15 | L12: 확인중 | O12: TSMADLN19 | P12: Numeric | Q12: 15 | R12: 이지론한도 | S12: ○ | X12: =SUM(X3:X11) -> 315
A13: =IF(D12=D13,A12+1,1) -> 11 | B13: 1) 심사 대상 정보 (분석계) | C13: TBGEAA209 | D13: GEA신용회원사전대상자내역 | E13: 이지론대출금리 | F13: 이지론대출금리 | H13: N | I13: NUMBER | J13: 9 | K13: 5 | L13: 확인중 | O13: TSMADLN19 | P13: Numeric | Q13: 9.5 | R13: 대출이율 | S13: ○
A14: =IF(D13=D14,A13+1,1) -> 12 | B14: 1) 심사 대상 정보 (분석계) | C14: TBGEAA209 | D14: GEA신용회원사전대상자내역 | E14: 연간원리금상환금액 | F14: 연간원리금상환금액 | H14: N | I14: NUMBER | J14: 15 | L14: 확인중 | O14: TSMADLN19 | P14: Numeric | Q14: 15 | R14: 연원리금상환금액 | S14: ○
A15: =IF(D14=D15,A14+1,1) -> 13 | B15: 1) 심사 대상 정보 (분석계) | C15: TBGEAA209 | D15: GEA신용회원사전대상자내역 | E15: 유효가맹점여부 | F15: 유효가맹점여부 | I15: VARCHAR2 | J15: 1 | L15: 확인중 | O15: TSMADLA19 | P15: String | Q15: 1 | R15: 유효가맹점여부 | S15: ○
A16: =IF(D15=D16,A15+1,1) -> 14 | B16: 1) 심사 대상 정보 (분석계) | C16: TBGEAA209 | D16: GEA신용회원사전대상자내역 | E16: 유효사업자여부 | F16: 유효사업자여부 | I16: VARCHAR2 | J16: 1 | L16: 확인중 | O16: TSMADLA19 | P16: String | Q16: 1 | R16: 유효사업자여부 | S16: ○
A17: =IF(D16=D17,A16+1,1) -> 15 | B17: 1) 심사 대상 정보 (분석계) | C17: TBGEAA209 | D17: GEA신용회원사전대상자내역 | E17: 론니즈등급구분코드 | F17: 카드론니즈등급구분코드 | I17: VARCHAR2 | J17: 2 | L17: 확인중 | O17: TSMADLN19 | P17: String | Q17: 2 | R17: 론니즈등급구분 | S17: ○
A18: =IF(D17=D18,A17+1,1) -> 16 | B18: 1) 심사 대상 정보 (분석계) | C18: TBGEAA209 | D18: GEA신용회원사전대상자내역 | E18: 신용등급코드 | F18: 신용등급코드 | I18: VARCHAR2 | J18: 4 | L18: 확인중 | O18: TSMADLN19 | P18: String | Q18: 4 | R18: 신용등급코드 | S18: ○
A19: =IF(D18=D19,A18+1,1) -> 17 | B19: 1) 심사 대상 정보 (분석계) | C19: TBGEAA209 | D19: GEA신용회원사전대상자내역 | E19: KCB신용평가점수내용 | F19: KCB신용평가점수내용 | H19: N | I19: NUMBER | J19: 4 | L19: 확인중 | O19: TSMADLN19 | P19: Numeric | Q19: 4 | R19: 신용평점일련번호 | S19: ○
A20: =IF(D19=D20,A19+1,1) -> 18 | B20: 1) 심사 대상 정보 (분석계) | C20: TBGEAA209 | D20: GEA신용회원사전대상자내역 | E20: 최근3개월채권잔액 | F20: 최근3개월채권평잔 | H20: N | I20: NUMBER | J20: 15 | L20: 확인중 | O20: TSMADLN19 | P20: Numeric | Q20: 15 | R20: 최근3개월카드채권평잔 | S20: ○
A21: =IF(D20=D21,A20+1,1) -> 19 | B21: 1) 심사 대상 정보 (분석계) | C21: TBGEAA209 | D21: GEA신용회원사전대상자내역 | E21: 신규고객여부 | F21: 신규카드발급2개월초과여부 | I21: VARCHAR2 | J21: 1 | L21: 확인중 | O21: TSMADLN19 | P21: String | Q21: 1 | R21: 신규기존여부 | S21: ○
A22: =IF(D21=D22,A21+1,1) -> 20 | B22: 1) 심사 대상 정보 (분석계) | C22: TBGEAA209 | D22: GEA신용회원사전대상자내역 | E22: 최근12개월카드론평잔 | F22: 최근12개월카드론평잔 | H22: N | I22: NUMBER | J22: 15 | L22: 확인중 | O22: TSMADLN19 | P22: Numeric | Q22: 15 | R22: 최근12개월카드론평잔 | S22: ○
A23: =IF(D22=D23,A22+1,1) -> 21 | B23: 1) 심사 대상 정보 (분석계) | C23: TBGEAA209 | D23: GEA신용회원사전대상자내역 | E23: 월가처분소득금액 | F23: 월가처분소득금액 | H23: N | I23: NUMBER | J23: 15 | L23: 확인중 | O23: TSMADLN19 | P23: Numeric | Q23: 15 | R23: 월가처분소득금액 | S23: ○
A24: =IF(D23=D24,A23+1,1) -> 22 | B24: 1) 심사 대상 정보 (분석계) | C24: TBGEAA209 | D24: GEA신용회원사전대상자내역 | E24: 등급별최대한도금액 | F24: 결합등급한도금액 | H24: N | I24: NUMBER | J24: 15 | L24: 확인중 | O24: TSMADLN19 | P24: Numeric | Q24: 15 | R24: 등급별최고한도 | S24: ○
A25: =IF(D24=D25,A24+1,1) -> 23 | B25: 1) 심사 대상 정보 (분석계) | C25: TBGEAA209 | D25: GEA신용회원사전대상자내역 | E25: 연령한도제한금액 | F25: 연령한도제한금액 | H25: N | I25: NUMBER | J25: 15 | L25: 확인중 | O25: TSMADLN19 | P25: Numeric | Q25: 15 | R25: 연령별한도 | S25: ○
A26: =IF(D25=D26,A25+1,1) -> 24 | B26: 1) 심사 대상 정보 (분석계) | C26: TBGEAA209 | D26: GEA신용회원사전대상자내역 | E26: 이용가능한도미사용금액 | F26: 이용가능한도미사용금액 | H26: N | I26: NUMBER | J26: 15 | L26: 확인중 | O26: TSMADLN19 | P26: Numeric | Q26: 15 | R26: 이용가능한도미사용금액 | S26: ○
A27: =IF(D26=D27,A26+1,1) -> 25 | B27: 1) 심사 대상 정보 (분석계) | C27: TBGEAA209 | D27: GEA신용회원사전대상자내역 | E27: CSM연소득금액 | F27: CSM연소득금액 | H27: N | I27: NUMBER | J27: 15 | L27: 확인중 | O27: TSMADLN19 | P27: Numeric | Q27: 15 | R27: CSM연소득금액 | S27: ○
A28: =IF(D27=D28,A27+1,1) -> 26 | B28: 1) 심사 대상 정보 (분석계) | C28: TBGEAA209 | D28: GEA신용회원사전대상자내역 | E28: 만기일시한도금액 | F28: 이지론일시상환한도금액 | H28: N | I28: NUMBER | J28: 15 | L28: 확인중 | O28: TSMADLN19 | P28: Numeric | Q28: 15 | R28: 만기일시한도 | S28: ○
A29: =IF(D28=D29,A28+1,1) -> 27 | B29: 1) 심사 대상 정보 (분석계) | C29: TBGEAA209 | D29: GEA신용회원사전대상자내역 | E29: 낙아웃구제대상여부 | F29: 이지누리론낙아웃구제대상여부 | I29: VARCHAR2 | J29: 1 | L29: 확인중 | O29: TSMADLN19 | P29: String | Q29: 1 | R29: 구제대상여부 | S29: ○
A30: =IF(D29=D30,A29+1,1) -> 28 | B30: 1) 심사 대상 정보 (분석계) | C30: TBGEAA209 | D30: GEA신용회원사전대상자내역 | E30: 이지론소액한도대상여부 | F30: 이지누리론소액한도대상여부 | I30: VARCHAR2 | J30: 1 | L30: 확인중 | O30: TSMADLN19 | P30: String | Q30: 1 | R30: 소액한도대상여부 | S30: ○
A31: =IF(D30=D31,A30+1,1) -> 29 | B31: 1) 심사 대상 정보 (분석계) | C31: TBGEAA209 | D31: GEA신용회원사전대상자내역 | E31: 이지론최장거치개월수 | F31: 이지론거치기간수 | H31: N | I31: NUMBER | J31: 5 | L31: 확인중 | O31: TSMADLN19 | P31: Numeric | Q31: 5 | R31: 최장거치개월수 | S31: ○
A32: =IF(D31=D32,A31+1,1) -> 30 | B32: 1) 심사 대상 정보 (분석계) | C32: TBGEAA209 | D32: GEA신용회원사전대상자내역 | E32: 이지론최장대출기간월수 | F32: 이지론분할상환대출기간수 | H32: N | I32: NUMBER | J32: 5 | L32: 확인중 | O32: TSMADLN19 | P32: Numeric | Q32: 5 | R32: 최장대출기간월수 | S32: ○
A33: =IF(D32=D33,A32+1,1) -> 31 | B33: 1) 심사 대상 정보 (분석계) | C33: TBGEAA209 | D33: GEA신용회원사전대상자내역 | E33: 일반대출인정기준년월 | F33: 이지론플러스대출자격유효년월 | I33: VARCHAR2 | J33: 6 | L33: 확인중 | O33: TSMADLN19 | P33: String | Q33: 6 | R33: 일반대출인정기준년월 | S33: ○
A34: =IF(D33=D34,A33+1,1) -> 32 | B34: 1) 심사 대상 정보 (분석계) | C34: TBGEAA209 | D34: GEA신용회원사전대상자내역 | E34: 일반대출인정금액 | F34: 이지론플러스이전한도금액 | H34: N | I34: NUMBER | J34: 15 | L34: 확인중 | O34: TSMADLN19 | P34: Numeric | Q34: 15 | R34: 일반대출인정금액 | S34: ○
A35: =IF(D34=D35,A34+1,1) -> 33 | B35: 1) 심사 대상 정보 (분석계) | C35: TBGEAA209 | D35: GEA신용회원사전대상자내역 | E35: TM적용한도금액 | F35: 이지론증액한도금액 | H35: N | I35: NUMBER | J35: 15 | L35: 확인중 | O35: TSMADLN19 | P35: Numeric | Q35: 15 | R35: TM적용한도 | S35: ○
A36: =IF(D35=D36,A35+1,1) -> 34 | B36: 1) 심사 대상 정보 (분석계) | C36: TBGEAA209 | D36: GEA신용회원사전대상자내역 | E36: 신용BSS산정대상구분코드 | F36: 신용BSS산정대상구분코드 | I36: VARCHAR2 | J36: 3 | L36: 확인중 | O36: TSMADLN19 | P36: String | Q36: 3 | R36: 신용BSS산정대상구분 | S36: ○
A37: =IF(D36=D37,A36+1,1) -> 35 | B37: 1) 심사 대상 정보 (분석계) | C37: TBGEAA209 | D37: GEA신용회원사전대상자내역 | E37: 통합카드BSS모형구분코드 | F37: 통합카드BSS모형구분코드 | I37: VARCHAR2 | J37: 2 | L37: 확인중 | O37: TSMADLN19 | P37: String | Q37: 2 | R37: 신용BSS모형구분 | S37: ○
A38: =IF(D37=D38,A37+1,1) -> 36 | B38: 1) 심사 대상 정보 (분석계) | C38: TBGEAA209 | D38: GEA신용회원사전대상자내역 | E38: 신용카드BSS평가점수 | F38: 신용카드BSS평가점수 | H38: N | I38: NUMBER | J38: 5 | L38: 확인중 | O38: TSMADLN19 | P38: Numeric | Q38: 5 | R38: 신용BSS평점 | S38: ○
A39: =IF(D38=D39,A38+1,1) -> 37 | B39: 1) 심사 대상 정보 (분석계) | C39: TBGEAA209 | D39: GEA신용회원사전대상자내역 | E39: 신용BSS등급구분코드 | F39: 신용BSS등급구분코드 | I39: VARCHAR2 | J39: 2 | L39: 확인중 | O39: TSMADLN19 | P39: String | Q39: 2 | R39: 신용BSS등급 | S39: ○
A40: =IF(D39=D40,A39+1,1) -> 38 | B40: 1) 심사 대상 정보 (분석계) | C40: TBGEAA209 | D40: GEA신용회원사전대상자내역 | E40: 카드론신규모형구분코드 | F40: 카드론신규모형구분코드 | I40: VARCHAR2 | J40: 2 | L40: 확인중 | O40: TSMADLN19 | P40: String | Q40: 2 | R40: 카드론신규모형구분 | S40: ○
...

Sheet RCLIPS송신(이지론)_최종
A1: Seq | B1: RCLIPS코드 | C1: 속성 | D1: 길이 | E1: R클립스_항목명 | F1: 구분 | G1: R클립스_비고 | H1: 원천정보그룹 | I1: 원천정보(원본) | J1: MDD_호출CPBI/EBI | K1: MDD_항목명 | L1: CB사 항목코드 | M1: CB사 전문번호 | N1: BITMAP | O1: 변경구분 | P1: 비고2(개발팀) | Q1: 필수입력
A2: =ROW()-1 -> 1 | B2: PKG_ID | C2: String | D2: 20 | E2: Online_C9_ASS
A3: =ROW()-1 -> 2 | B3: CNT | C3: Numeric | D3: 3 | E3: 제공항목건수 | G3: 항목코드5+항목값15
A4: =ROW()-1 -> 3 | B4: A1000 | C4: String | D4: 14 | E4: 접수번호 | F4: 제공항목 | H4: 내부정보 | I4: GEA심사사전정보내역 | J4: i카드론대출RCLIPS전문조립C | K4: 카드론신청서접수번호
A5: =ROW()-1 -> 4 | B5: A1001 | C5: String | D5: 2 | E5: 상품코드 | F5: 제공항목 | H5: 내부정보 | I5: GEA심사사전정보내역 | J5: i카드론대출RCLIPS전문조립C | K5: 카드론평가상품구분코드
A6: =ROW()-1 -> 5 | B6: A1004 | C6: Numeric | D6: 5 | E6: 연령 | F6: 제공항목 | H6: 내부정보 | I6: GEA심사사전정보내역 | J6: i카드론대출RCLIPS전문조립C | K6: 주민등록번호 | O6: 삭제
A7: =ROW()-1 -> 6 | B7: A1005 | C7: String | D7: 1 | E7: 외국인여부 | F7: 제공항목 | H7: 내부정보 | I7: GEA심사사전정보내역 | J7: 심사사전정보내역조회C > GEA심사사전정보내역 | K7: 고객고유번호구분코드 | O7: 삭제
A8: =ROW()-1 -> 7 | B8: A2000 | C8: Numeric | D8: 15 | E8: 중고차대출잔액 | F8: 제공항목 | G8: [r고객별상품별잔액조회C].[중고차오토론잔액_N18] | H8: 내부정보 | I8: GEA심사사전정보내역 | J8: 심사사전정보내역조회C > 현재일자기준대출심사모형사전조회 | K8: 중고차대출잔액 | O8: 추가 | P8: 20190514 추가 (유지수D,이관용C 메신저협의완료 - 현업문서에는 미존재함)
A9: =ROW()-1 -> 8 | B9: A2001 | C9: String | D9: 1 | E9: 여신연체고객(KB 국민은행정보) | F9: 제공항목 | G9: 103 | H9: 내부정보 | I9: GEA심사사전정보내역 | J9: 심사사전정보내역조회C > 현재일자기준대출심사모형사전조회 | K9: IF (불가사유코드_V3 = 103) THEN 0 ELSE 1 END
A10: =ROW()-1 -> 9 | B10: A2002 | C10: String | D10: 1 | E10: 신용카드 거래정지 등록고객 | F10: 제공항목 | G10: 006 | H10: 내부정보 | I10: GEA심사사전정보내역 | J10: 심사사전정보내역조회C > 현재일자기준대출심사모형사전조회 | K10: IF (불가사유코드_V3 = 006) THEN 0 ELSE 1 END
A11: =ROW()-1 -> 10 | B11: A2003 | C11: String | D11: 1 | E11: 신용관리대상 및 당행정보관리 등재고객(KB 국민은행 정보) | F11: 제공항목 | G11: 014 | H11: 내부정보 | I11: GEA심사사전정보내역 | J11: 심사사전정보내역조회C > 현재일자기준대출심사모형사전조회 | K11: IF (불가사유코드_V3 = 014) THEN 0 ELSE 1 END
A12: =ROW()-1 -> 11 | B12: X | C12: String | D12: 1 | E12: NICE 타사연체정보 보유고객(신용정보) | F12: 제공항목 | H12: 내부정보 | I12: GEA심사사전정보내역 | J12: #N/A | K12: #N/A | O12: 삭제 | P12: 20190325이전기삭제됨
A13: =ROW()-1 -> 12 | B13: X | C13: String | D13: 1 | E13: KCB 타사연체정보 보유고객(신용정보) | F13: 제공항목 | H13: 내부정보 | I13: GEA심사사전정보내역 | J13: #N/A | K13: #N/A | O13: 삭제 | P13: 20190325이전기삭제됨
A14: =ROW()-1 -> 13 | B14: A2006 | C14: String | D14: 1 | E14: 사망실종 고객(고객정보) | F14: 제공항목 | G14: 001 | H14: 내부정보 | I14: GEA심사사전정보내역 | J14: 심사사전정보내역조회C > 현재일자기준대출심사모형사전조회 | K14: IF (불가사유코드_V3 = 001) THEN 0 ELSE 1 END
A15: =ROW()-1 -> 14 | B15: A2007 | C15: String | D15: 1 | E15: 거래주의보정보 등록고객(고객정보) | F15: 제공항목 | G15: 003 | H15: 내부정보 | I15: GEA심사사전정보내역 | J15: 심사사전정보내역조회C > 현재일자기준대출심사모형사전조회 | K15: IF (불가사유코드_V3 = 003) THEN 0 ELSE 1 END
A16: =ROW()-1 -> 15 | B16: A2008 | C16: String | D16: 1 | E16: 워크아웃 등록고객 | F16: 제공항목 | G16: 005 | H16: 내부정보 | I16: GEA심사사전정보내역 | J16: 심사사전정보내역조회C > 현재일자기준대출심사모형사전조회 | K16: IF (불가사유코드_V3 = 005) THEN 0 ELSE 1 END
A17: =ROW()-1 -> 16 | B17: A2009 | C17: String | D17: 1 | E17: 장기카드대출 연체고객 | F17: 제공항목 | G17: 008 | H17: 내부정보 | I17: GEA심사사전정보내역 | J17: 심사사전정보내역조회C > 현재일자기준대출심사모형사전조회 | K17: IF (불가사유코드_V3 = 008) THEN 0 ELSE 1 END
A18: =ROW()-1 -> 17 | B18: A2010 | C18: String | D18: 1 | E18: 요주의 등록고객(신용정보) | F18: 제공항목 | G18: 009 | H18: 내부정보 | I18: GEA심사사전정보내역 | J18: 심사사전정보내역조회C > 현재일자기준대출심사모형사전조회 | K18: IF (불가사유코드_V3 = 009) THEN 0 ELSE 1 END
A19: =ROW()-1 -> 18 | B19: A2011 | C19: String | D19: 1 | E19: 신용불량 채무관계제한 등록고객(신용정보) | F19: 제공항목 | G19: 010 | H19: 내부정보 | I19: GEA심사사전정보내역 | J19: 심사사전정보내역조회C > 현재일자기준대출심사모형사전조회 | K19: IF (불가사유코드_V3 = 010) THEN 0 ELSE 1 END
A20: =ROW()-1 -> 19 | B20: A2012 | C20: String | D20: 1 | E20: 은행 사전채무조정 신청자 및 확정자 등록고객(KB 국민은행 정보) | F20: 제공항목 | G20: 015 | H20: 내부정보 | I20: GEA심사사전정보내역 | J20: 심사사전정보내역조회C > 현재일자기준대출심사모형사전조회 | K20: IF (불가사유코드_V3 = 015) THEN 0 ELSE 1 END
A21: =ROW()-1 -> 20 | B21: A2013 | C21: String | D21: 1 | E21: 고객기본정보 구분코드 오류(고객정보) | F21: 제공항목 | G21: 016 | H21: 내부정보 | I21: GEA심사사전정보내역 | J21: 심사사전정보내역조회C > 현재일자기준대출심사모형사전조회 | K21: IF (불가사유코드_V3 = 016) THEN 0 ELSE 1 END
A22: =ROW()-1 -> 21 | B22: A2014 | C22: Numeric | D22: 15 | E22: 카드론대출잔액 | F22: 제공항목 | G22: GEA카드론계약기본대출잔액조회 | H22: 내부정보 | I22: GEA심사사전정보내역 | J22: 심사사전정보내역조회C > 현재일자기준대출심사모형사전조회 | K22: 카드론대출잔액
A23: =ROW()-1 -> 22 | B23: A2015 | C23: Numeric | D23: 15 | E23: 오토론대출잔액 | F23: 제공항목 | G23: [rGEA카드론계약기본대출잔액조회E].[오토론대출잔액] + [r고객별상품별잔액조회C].[신차오토론잔액_N18] | H23: 내부정보 | I23: GEA심사사전정보내역 | J23: 심사사전정보내역조회C > 현재일자기준대출심사모형사전조회 | K23: 오토론대출잔액
A24: =ROW()-1 -> 23 | B24: A2016 | C24: Numeric | D24: 15 | E24: 신용대출잔액 | F24: 제공항목 | G24: GEA카드론계약기본대출잔액조회 | H24: 내부정보 | I24: GEA심사사전정보내역 | J24: 심사사전정보내역조회C > 현재일자기준대출심사모형사전조회 | K24: 신용대출잔액
A25: =ROW()-1 -> 24 | B25: A2017 | C25: Numeric | D25: 15 | E25: 대환론대출잔액 | F25: 제공항목 | G25: GEA카드론계약기본대출잔액조회 | H25: 내부정보 | I25: GEA심사사전정보내역 | J25: 심사사전정보내역조회C > 현재일자기준대출심사모형사전조회 | K25: 대환론대출잔액
... A27: =ROW()-1 -> 26 | B27: A2019 | C27: Numeric | D27: 15 | E27: 당사 신용카드 잔액 | F27: 제공항목 | G27: --> | H27: 내부정보 | I27: GEA심사사전정보내역 | J27: 심사사전정보내역조회C > 현재일자기준대출심사모형사전조회 | K27: 당사신용카드잔액 [bd당사신용카드잔액] = [r심사사전정보내역조회C].[현재일자기준대출심사모형사전조회출력Dto].[LS연체원금_N15] + [r심사사전정보내역조회C].[현재일자기준대출심사모형사전조회출력Dto].[LS청구원금_N15] + [r심사사전정보내역조회C].[현재일자기준대출심사모형사전조회출력Dto].[IS연체원금_N15] + [r심사사전정보내역조회C].[현재일자기준대출심사모형사전조회출력Dto].[IS미청구원금_N15] + [r심사사전정보내역조회C].[현재일자기준대출심사모형사전조회출력Dto].[CA연체원금] + [r심사사전정보내역조회C].[현재일자기준대출심사모형사전조회출력Dto].[CA청구원금] + [r심사사전정보내역조회C].[현재일자기준대출심사모형사전조회출력Dto].[CAI연체원금_N15] + [r심사사전정보내역조회C].[현재일자기준대출심사모형사전조회출력Dto].[CAI미청구원금_N15] + [r심사사전정보내역조회C].[현재일자기준대출심사모형사전조회출력Dto].[RCA연체원금_N15] + [r심사사전정보내역조회C].[현재일자기준대출심사모형사전조회출력Dto].[RCA이월금액_N15] + [r심사사전정보내역조회C].[현재일자기준대출심사모형사전조회출력Dto].[RCA미청구원금_N15] + [r심사사전정보내역조회C].[현재일자기준대출심사모형사전조회출력Dto].[RLS연체원금_N15] + [r심사사전정보내역조회C].[현재일자기준대출심사모형사전조회출력Dto].[RLS이월금액_N15] + [r심사사전정보내역조회C].[현재일자기준대출심사모형사전조회출력Dto].[RLS미청구원금_N15];
A28: =ROW()-1 -> 27 | B28: A2020 | C28: String | D28: 1 | E28: 유효회원여부 | F28: 제공항목 | H28: 내부정보 | I28: GEA심사사전정보내역 | J28: 심사사전정보내역조회C > 현재일자기준대출심사모형사전조회 | K28: KB카드유효회원여부
A29: =ROW()-1 -> 28 | B29: A2021 | C29: String | D29: 1 | E29: 유효고객여부 | F29: 제공항목 | G29: rCI연계정보고객번호상호조회C (GAA) | H29: 내부정보 | I29: GEA심사사전정보내역 | J29: 심사사전정보내역조회C > 현재일자기준대출심사모형사전조회 | K29: KB카드유효고객여부
A30: =ROW()-1 -> 29 | B30: A2022 | C30: String | D30: 1 | E30: 신용카드소지여부 | F30: 제공항목 | G30: r고객식별자유효카드존재여부조회 (GAG) | H30: 내부정보 | I30: GEA심사사전정보내역 | J30: 심사사전정보내역조회C > 현재일자기준대출심사모형사전조회 | K30: 유효신용카드소지여부
A31: =ROW()-1 -> 30 | B31: A2023 | C31: String | D31: 1 | E31: 체크카드보유여부 | F31: 제공항목 | G31: r고객식별자유효카드존재여부조회 | H31: 내부정보 | I31: GEA심사사전정보내역 | J31: 심사사전정보내역조회C > 현재일자기준대출심사모형사전조회 | K31: 유효체크카드소지여부
A32: =ROW()-1 -> 31 | B32: A2024 | C32: String | D32: 1 | E32: 가맹점대표자여부 | F32: 제공항목 | G32: r가맹점매출실적산출 (GDB) | H32: 내부정보 | I32: GEA심사사전정보내역 | J32: 심사사전정보내역조회C > 현재일자기준대출심사모형사전조회 | K32: 가맹점대표자여부
A33: =ROW()-1 -> 32 | B33: A2025 | C33: String | D33: 2 | E33: 가맹점주등급 | F33: 제공항목 | H33: 내부정보 | I33: GEA심사사전정보내역 | J33: 심사사전정보내역조회C > 가맹점주등급조회E | K33: 미정
A34: =ROW()-1 -> 33 | B34: A2026 | C34: Numeric | D34: 15 | E34: 최근 6개월 가맹점 매출액 | F34: 제공항목 | G34: r가맹점매출실적산출 | H34: 내부정보 | I34: GEA심사사전정보내역 | J34: 심사사전정보내역조회C > 실시간심사6개월가맹점매출금액조회E | K34: 최근6개월가맹점매출금액
A35: =ROW()-1 -> 34 | B35: A2027 | C35: Numeric | D35: 15 | E35: 당사 CA 잔액 | F35: 제공항목 | G35: --> | H35: 내부정보 | I35: GEA심사사전정보내역 | J35: 심사사전정보내역조회C > 현재일자기준대출심사모형사전조회 | K35: 당사CA잔액 [bdCA잔액] = [r심사사전정보내역조회C].[현재일자기준대출심사모형사전조회출력Dto].[CA연체원금] + [r심사사전정보내역조회C].[현재일자기준대출심사모형사전조회출력Dto].[CA청구원금] + [r심사사전정보내역조회C].[현재일자기준대출심사모형사전조회출력Dto].[CAI연체원금_N15] + [r심사사전정보내역조회C].[현재일자기준대출심사모형사전조회출력Dto].[CAI미청구원금_N15] + [r심사사전정보내역조회C].[현재일자기준대출심사모형사전조회출력Dto].[RCA연체원금_N15] + [r심사사전정보내역조회C].[현재일자기준대출심사모형사전조회출력Dto].[RCA이월금액_N15] + [r심사사전정보내역조회C].[현재일자기준대출심사모형사전조회출력Dto].[RCA미청구원금_N15];
A36: =ROW()-1 -> 35 | B36: A2028 | C36: Numeric | D36: 15 | E36: 당사 RLS이월잔액 | F36: 제공항목 | G36: r심사전략고도화결제금액조회C (GBC) | H36: 내부정보 | I36: GEA심사사전정보내역 | J36: 심사사전정보내역조회C > 현재일자기준대출심사모형사전조회 | K36: RLS이월금액_N15
A37: =ROW()-1 -> 36 | B37: A2029 | C37: Numeric | D37: 15 | E37: 당사 RCA이월잔액 | F37: 제공항목 | G37: r심사전략고도화결제금액조회C | H37: 내부정보 | I37: GEA심사사전정보내역 | J37: 심사사전정보내역조회C > 현재일자기준대출심사모형사전조회 | K37: RCA이월금액_N15
A38: =ROW()-1 -> 37 | B38: A2030 | C38: Numeric | D38: 15 | E38: 쉬프트론대출잔액 | F38: 제공항목 | G38: [rGEA카드론계약기본대출잔액조회E].[전환대출잔액_N15] | H38: 내부정보 | I38: GEA심사사전정보내역 | J38: 심사사전정보내역조회C > 현재일자기준대출심사모형사전조회 | K38: 전환대출잔액_N15
A39: =ROW()-1 -> 38 | B39: A2031 | C39: Numeric | D39: 15 | E39: 매입할부금융잔액 | F39: 제공항목 | G39: [r고객별상품별잔액조회C].[SY캐피탈오토할부잔액_N18]; | H39: 내부정보 | I39: GEA심사사전정보내역 | J39: 심사사전정보내역조회C > 현재일자기준대출심사모형사전조회 | K39: 매입할부금융잔액_N15
A40: =ROW()-1 -> 39 | B40: A2032 | C40: Numeric | D40: 15 | E40: 부채증명서 발급 경과일수 (단위: 일) | F40: 제공항목 | G40: [r부채증명서발급정보조회C] (GFA) | H40: 내부정보 | I40: GEA심사사전정보내역 | J40: 심사사전정보내역조회C > 부채증명서발급정보조회 | K40: 부채증명서발급경과일수
A41: =ROW()-1 -> 40 | B41: A2033 | C41: Numeric | D41: 15 | E41: TOTAL CREDIT | F41: 제공항목 | G41: 0 | H41: 내부정보 | I41: GEA심사사전정보내역 | J41: N/A (요건미정의로 초기값설정) | K41: N/A (요건미정의로 초기값설정)
...

Sheet RCLIPS수신(이지론)_최종
A1: < 카드론 > | H1: #N/A 테이블에 저장안함
A2: * RCLIPS → 처리계 | H2: s붙은건 MDD항목명
A3: NO | B3: 원천구분 | C3: R-Clips 코드 | D3: 항목명 | E3: 형식 | F3: 길이 | G3: 구분 | H3: TBGEAA204, MDD항목 | I3: 비고(현업) | J3: 비고(NEW) | K3: 비고(OLD)
A4: =ROW()-3 -> 1 | B4: RCLIPS | D4: 결과코드 | E4: String | F4: 4 | I4: 0000이 아닐 경우 오류
A5: =ROW()-3 -> 2 | B5: RCLIPS | D5: 결과건수 | E5: Numeric | F5: 3 | I5: 결과항목(코드5+값15) 건수
A6: =ROW()-3 -> 3 | B6: RCLIPS | D6: 기준년월 | E6: String | F6: 6
A7: =ROW()-3 -> 4 | B7: RCLIPS | D7: 접수번호 | E7: String | F7: 14
A8: =ROW()-3 -> 5 | B8: RCLIPS | D8: 고객식별자 | E8: String | F8: 10
A9: =ROW()-3 -> 6 | B9: RCLIPS | D9: 회원일련번호 | E9: String | F9: 8
A10: =ROW()-3 -> 7 | B10: RCLIPS | C10: R0001 | D10: 상품코드 | E10: String | F10: 2 | G10: 결과항목 | H10: =VLOOKUP(C10,$L$10:$N$135,2,FALSE) -> #N/A | J10: E컬럼 #N/A 항목, TBGEAA204에 저장하거나 , MDD 항목으로 출력안함. 현업참고 | L10: A4060 | M10: s비대면연계대출등급 | P10: =VLOOKUP(L10,$C$11:$D$152,1,FALSE) -> #N/A
A11: =ROW()-3 -> 8 | B11: RCLIPS | C11: R1002 | D11: 최종대출가능금액_사전 | E11: Numeric | F11: 15 | G11: 결과항목 | H11: =VLOOKUP(C11,$L$10:$N$135,2,FALSE) -> 사전최종한도금액 | L11: A3075 | M11: s중금리ML스코어신용등급코드 | P11: =VLOOKUP(L11,$C$11:$D$152,1,FALSE) -> #N/A
A12: =ROW()-3 -> 9 | B12: RCLIPS | C12: R0002 | D12: 최종대출가능금액_실시간 | E12: Numeric | F12: 15 | G12: 결과항목 | H12: =VLOOKUP(C12,$L$10:$N$135,2,FALSE) -> 실시간최종한도금액 | L12: M1004 | M12: s결합등급 | P12: =VLOOKUP(L12,$C$11:$D$152,1,FALSE) -> #N/A
A13: =ROW()-3 -> 10 | B13: RCLIPS | C13: R1060 | D13: 일시한도_사전 | E13: Numeric | F13: 15 | G13: 결과항목 | H13: =VLOOKUP(C13,$L$10:$N$135,2,FALSE) -> 사전일시상환한도금액 | L13: R1002 | M13: 사전최종한도금액 | P13: =VLOOKUP(L13,$C$11:$D$152,1,FALSE) -> R1002
A14: =ROW()-3 -> 11 | B14: RCLIPS | C14: R0060 | D14: 일시한도_실시간 | E14: Numeric | F14: 15 | G14: 결과항목 | H14: =VLOOKUP(C14,$L$10:$N$135,2,FALSE) -> 실시간일시상환한도금액 | L14: R0002 | M14: 실시간최종한도금액 | P14: =VLOOKUP(L14,$C$11:$D$152,1,FALSE) -> R0002
A15: =ROW()-3 -> 12 | B15: RCLIPS | C15: R1061 | D15: TM한도_사전 | E15: Numeric | F15: 15 | G15: 결과항목 | H15: =VLOOKUP(C15,$L$10:$N$135,2,FALSE) -> 사전이지론증액한도금액 | L15: R1060 | M15: 사전일시상환한도금액 | P15: =VLOOKUP(L15,$C$11:$D$152,1,FALSE) -> R1060
A16: =ROW()-3 -> 13 | B16: RCLIPS | C16: R0061 | D16: TM한도_실시간 | E16: Numeric | F16: 15 | G16: 결과항목 | H16: =VLOOKUP(C16,$L$10:$N$135,2,FALSE) -> 실시간이지론증액한도금액 | L16: R0060 | M16: 실시간일시상환한도금액 | P16: =VLOOKUP(L16,$C$11:$D$152,1,FALSE) -> R0060
A17: =ROW()-3 -> 14 | B17: RCLIPS | C17: R1003 | D17: 대출이율_사전 | E17: Numeric | F17: 9 | G17: 결과항목 | H17: =VLOOKUP(C17,$L$10:$N$135,2,FALSE) -> 사전적용이율 | L17: R1061 | M17: 사전이지론증액한도금액 | P17: =VLOOKUP(L17,$C$11:$D$152,1,FALSE) -> R1061
A18: =ROW()-3 -> 15 | B18: RCLIPS | C18: R0003 | D18: 대출이율_실시간 | E18: Numeric | F18: 9 | G18: 결과항목 | H18: =VLOOKUP(C18,$L$10:$N$135,2,FALSE) -> 실시간적용이율 | L18: R0061 | M18: 실시간이지론증액한도금액 | P18: =VLOOKUP(L18,$C$11:$D$152,1,FALSE) -> R0061
A19: =ROW()-3 -> 16 | B19: RCLIPS | C19: R1004 | D19: 변경전금리등급 | E19: String | F19: 2 | G19: 결과항목 | H19: =VLOOKUP(C19,$L$10:$N$135,2,FALSE) -> 사전금리등급구분코드 | J19: 20190507 입력(A8036)값과 동일함 (이관용C 확인) | L19: R1003 | M19: 사전적용이율 | P19: =VLOOKUP(L19,$C$11:$D$152,1,FALSE) -> R1003
A20: =ROW()-3 -> 17 | B20: RCLIPS | C20: R0004 | D20: 금리등급_실시간 | E20: String | F20: 2 | G20: 결과항목 | H20: =VLOOKUP(C20,$L$10:$N$135,2,FALSE) -> 실시간금리등급구분코드 | J20: 20190507 입력(A2039, A8086)값으로 산출함 (이관용C 확인) | L20: R0003 | M20: 실시간적용이율 | P20: =VLOOKUP(L20,$C$11:$D$152,1,FALSE) -> R0003
A21: =ROW()-3 -> 18 | B21: RCLIPS | C21: R0062 | D21: 우수사업자여부 | E21: String | F21: 1 | G21: 결과항목 | H21: =VLOOKUP(C21,$L$10:$N$135,2,FALSE) -> #N/A | L21: R1004 | M21: 사전금리등급구분코드 | P21: =VLOOKUP(L21,$C$11:$D$152,1,FALSE) -> R1004
A22: =ROW()-3 -> 19 | B22: RCLIPS | C22: R0063 | D22: 우수가맹점여부 | E22: String | F22: 1 | G22: 결과항목 | H22: =VLOOKUP(C22,$L$10:$N$135,2,FALSE) -> #N/A | L22: R0004 | M22: 실시간금리등급구분코드 | P22: =VLOOKUP(L22,$C$11:$D$152,1,FALSE) -> R0004
A23: =ROW()-3 -> 20 | B23: RCLIPS | C23: R1005 | D23: 최장대출기간월수_사전 | E23: Numeric | F23: 5 | G23: 결과항목 | H23: =VLOOKUP(C23,$L$10:$N$135,2,FALSE) -> 사전최장대출기간수 | J23: 20190426 입력(A8026)값과 동일함 (이시정k 확인) | L23: R1005 | M23: 사전최장대출기간수 | P23: =VLOOKUP(L23,$C$11:$D$152,1,FALSE) -> R1005
A24: =ROW()-3 -> 21 | B24: RCLIPS | C24: R0005 | D24: 최장대출기간월수_실시간 | E24: Numeric | F24: 5 | G24: 결과항목 | H24: =VLOOKUP(C24,$L$10:$N$135,2,FALSE) -> 실시간최장대출기간수 | L24: R0005 | M24: 실시간최장대출기간수 | P24: =VLOOKUP(L24,$C$11:$D$152,1,FALSE) -> R0005
A25: =ROW()-3 -> 22 | B25: RCLIPS | C25: R1006 | D25: 최장거치개월수_사전 | E25: Numeric | F25: 5 | G25: 결과항목 | H25: =VLOOKUP(C25,$L$10:$N$135,2,FALSE) -> 사전최장거치기간수 | L25: R1006 | M25: 사전최장거치기간수 | P25: =VLOOKUP(L25,$C$11:$D$152,1,FALSE) -> R1006
A26: =ROW()-3 -> 23 | B26: RCLIPS | C26: R0006 | D26: 최장거치개월수_실시간 | E26: Numeric | F26: 5 | G26: 결과항목 | H26: =VLOOKUP(C26,$L$10:$N$135,2,FALSE) -> 실시간최장거치기간수 | L26: R0006 | M26: 실시간최장거치기간수 | P26: =VLOOKUP(L26,$C$11:$D$152,1,FALSE) -> R0006
A27: =ROW()-3 -> 24 | B27: RCLIPS | C27: R1064 | D27: 이용가능한도미사용금액_사전 | E27: String | F27: 4 | G27: 결과항목 | H27: =VLOOKUP(C27,$L$10:$N$135,2,FALSE) -> 사전이용가능한도미사용금액 | L27: R1064 | M27: 사전이용가능한도미사용금액 | P27: =VLOOKUP(L27,$C$11:$D$152,1,FALSE) -> R1064
A28: =ROW()-3 -> 25 | B28: RCLIPS | C28: R0064 | D28: 이용가능한도미사용금액_실시간 | E28: String | F28: 4 | G28: 결과항목 | H28: =VLOOKUP(C28,$L$10:$N$135,2,FALSE) -> 실시간이용가능한도미사용금액 | L28: R0064 | M28: 실시간이용가능한도미사용금액 | P28: =VLOOKUP(L28,$C$11:$D$152,1,FALSE) -> R0064
A29: =ROW()-3 -> 26 | B29: RCLIPS | C29: R0065 | D29: 취급불가여부 | E29: String | F29: 4 | G29: 결과항목 | H29: =VLOOKUP(C29,$L$10:$N$135,2,FALSE) -> 사전기타취급불가사유코드 | L29: R0065 | M29: 사전기타취급불가사유코드 | P29: =VLOOKUP(L29,$C$11:$D$152,1,FALSE) -> R0065
A30: =ROW()-3 -> 27 | B30: RCLIPS | C30: R1007 | D30: 대출탈락사유내용_사전 | E30: String | F30: 60 | G30: 결과항목 | H30: =VLOOKUP(C30,$L$10:$N$135,2,FALSE) -> 사전대출탈락사유 | L30: R1007 | M30: 사전대출탈락사유 | P30: =VLOOKUP(L30,$C$11:$D$152,1,FALSE) -> R1007
A31: =ROW()-3 -> 28 | B31: RCLIPS | C31: R0007 | D31: 대출탈락사유내용_실시간 | E31: String | F31: 60 | G31: 결과항목 | H31: =VLOOKUP(C31,$L$10:$N$135,2,FALSE) -> 실시간대출탈락사유 | L31: R0007 | M31: 실시간대출탈락사유 | P31: =VLOOKUP(L31,$C$11:$D$152,1,FALSE) -> R0007
A32: =ROW()-3 -> 29 | B32: RCLIPS | C32: R1087 | D32: 회원세그먼트구분_사전 | E32: String | F32: 2 | G32: 결과항목 | H32: =VLOOKUP(C32,$L$10:$N$135,2,FALSE) -> 사전회원세그먼트구분코드 | L32: R1087 | M32: 사전회원세그먼트구분코드 | P32: =VLOOKUP(L32,$C$11:$D$152,1,FALSE) -> R1087
A33: =ROW()-3 -> 30 | B33: RCLIPS | C33: R0087 | D33: 회원세그먼트구분_실시간 | E33: Numeric | F33: 2 | G33: 결과항목 | H33: =VLOOKUP(C33,$L$10:$N$135,2,FALSE) -> 실시간회원세그먼트구분코드 | L33: R0087 | M33: 실시간회원세그먼트구분코드 | P33: =VLOOKUP(L33,$C$11:$D$152,1,FALSE) -> R0087
A34: =ROW()-3 -> 31 | B34: RCLIPS | C34: R1010 | D34: KCB추정소득_사전 | E34: Numeric | F34: 15 | G34: 결과항목 | H34: =VLOOKUP(C34,$L$10:$N$135,2,FALSE) -> 사전KCB추정소득금액 | L34: R1010 | M34: 사전KCB추정소득금액 | P34: =VLOOKUP(L34,$C$11:$D$152,1,FALSE) -> R1010
A35: =ROW()-3 -> 32 | B35: RCLIPS | C35: R0010 | D35: KCB추정소득_실시간 | E35: Numeric | F35: 15 | G35: 결과항목 | H35: =VLOOKUP(C35,$L$10:$N$135,2,FALSE) -> 실시간KCB추정소득금액 | L35: R0010 | M35: 실시간KCB추정소득금액 | P35: =VLOOKUP(L35,$C$11:$D$152,1,FALSE) -> R0010
... A38: =ROW()-3 -> 35 | B38: RCLIPS | C38: R1012 | D38: 평균추정소득_사전 | E38: Numeric | F38: 15 | G38: 결과항목 | H38: =VLOOKUP(C38,$L$10:$N$135,2,FALSE) -> 사전평균추정소득금액 | L38: R1012 | M38: 사전평균추정소득금액 | P38: =VLOOKUP(L38,$C$11:$D$152,1,FALSE) -> R1012
A39: =ROW()-3 -> 36 | B39: RCLIPS | C39: R0012 | D39: 평균추정소득_실시간 | E39: Numeric | F39: 15 | G39: 결과항목 | H39: =VLOOKUP(C39,$L$10:$N$135,2,FALSE) -> 실시간평균추정소득금액 | I39: 금융소비자보호법 안내용 | L39: R0012 | M39: 실시간평균추정소득금액 | P39: =VLOOKUP(L39,$C$11:$D$152,1,FALSE) -> R0012
A40: =ROW()-3 -> 37 | B40: RCLIPS | C40: R1013 | D40: KCB연간원리금_사전 | E40: Numeric | F40: 15 | G40: 결과항목 | H40: =VLOOKUP(C40,$L$10:$N$135,2,FALSE) -> 사전KCB연간원리금상환금액 | L40: R1013 | M40: 사전KCB연간원리금상환금액 | P40: =VLOOKUP(L40,$C$11:$D$152,1,FALSE) -> R1013
A41: =ROW()-3 -> 38 | B41: RCLIPS | C41: R0013 | D41: KCB연간원리금_실시간 | E41: Numeric | F41: 15 | G41: 결과항목 | H41: =VLOOKUP(C41,$L$10:$N$135,2,FALSE) -> 실시간KCB연간원리금상환금액 | L41: R0013 | M41: 실시간KCB연간원리금상환금액 | P41: =VLOOKUP(L41,$C$11:$D$152,1,FALSE) -> R0013
A42: =ROW()-3 -> 39 | B42: RCLIPS | C42: R1014 | D42: NICE연간원리금_사전 | E42: Numeric | F42: 15 | G42: 결과항목 | H42: =VLOOKUP(C42,$L$10:$N$135,2,FALSE) -> 사전NICE연간원리금상환금액 | L42: R1014 | M42: 사전NICE연간원리금상환금액 | P42: =VLOOKUP(L42,$C$11:$D$152,1,FALSE) -> R1014
...

Sheet RCLIPS송신(일사천리론)_최종
A1: Seq | B1: RCLIPS코드 | C1: 속성 | D1: 길이 | E1: R클립스_항목명 | F1: 구분 | G1: R클립스_비고 | H1: 원천정보그룹 | I1: 원천정보(원본) | J1: MDD_호출CPBI/EBI | K1: MDD_항목명 | L1: CB사 항목코드 | M1: CB사 전문번호 | N1: BITMAP | O1: 변경구분 | P1: 비고2(개발팀)
A2: =ROW()-1 -> 1 | B2: A1001 | C2: Character | D2: 2 | E2: 상품코드 | F2: 내부항목 | G2: 비회원 = '18' | I2: GEA심사사전정보내역 | J2: i신용대출RCLIPS전문조립C | K2: 카드론평가상품구분코드 | L2: N/A
A3: =ROW()-1 -> 2 | B3: A1002 | C3: Numeric | D3: 9 | E3: 대출신청금액 | F3: 내부항목 | G3: '17.12 삭제 | I3: #N/A | J3: 삭제 | K3: 삭제 | L3: N/A | O3: 삭제 | P3: 20190325이전기삭제됨
A4: =ROW()-1 -> 3 | B4: A1003 | C4: Numeric | D4: 9 | E4: 대출희망기간 | F4: 내부항목 | G4: '17.12 삭제 | I4: #N/A | J4: 삭제 | K4: 삭제 | L4: N/A | O4: 삭제 | P4: 20190325이전기삭제됨
A5: =ROW()-1 -> 4 | B5: A1004 | C5: Numeric | D5: 9 | E5: 연령 | F5: 내부항목 | G5: 24세 이하 소득유의고객 | I5: GEA심사사전정보내역 | J5: i신용대출RCLIPS전문조립C | K5: 주민등록번호 | L5: N/A
A6: =ROW()-1 -> 5 | B6: A1005 | C6: Character | D6: 1 | E6: 외국인여부 | F6: 내부항목 | I6: GEA심사사전정보내역 | J6: 현재일자기준대출심사모형사전조회출력Dto | K6: 고객고유번호구분코드 | L6: +주민등록번호 5.6.7.8
A7: =ROW()-1 -> 6 | B7: A1006 | C7: Character | D7: 14 | E7: 접수번호 | F7: 내부항목 | I7: GEA심사사전정보내역 | J7: i신용대출RCLIPS전문조립C | K7: 카드론신청서접수번호 | L7: N/A
A8: =ROW()-1 -> 7 | B8: A1007 | C8: Character | D8: 2 | E8: 상품코드 | J8: i이지론플러스대출RCLIPS전문조립C | K8: 상품코드 | P8: A0002
A9: =ROW()-1 -> 8 | B9: A1008 | C9: Character | D9: 2 | E9: 신용대출심사결과 | J9: r신용대출심사결과조회E | K9: 대출평가결과구분코드 | P9: A0005
A10: =ROW()-1 -> 9 | B10: A2001 | C10: Character | D10: 1 | E10: 여신연체고객(KB 국민은행정보) | F10: 내부항목 | G10: KB카드실시간KO IN ('013') | I10: GEA심사사전정보내역 | J10: 현재일자기준대출심사모형사전조회출력Dto | K10: 013 | L10: N/A
A11: =ROW()-1 -> 10 | B11: A2002 | C11: Character | D11: 1 | E11: 신용카드 거래정지 등록고객 | F11: 내부항목 | G11: KB카드실시간KO IN ('006'), 회원별거래정지중 탈회는 재확인 필요 별도코드 신설 검토 | I11: GEA심사사전정보내역 | J11: 현재일자기준대출심사모형사전조회출력Dto | K11: 006 | L11: N/A
A12: =ROW()-1 -> 11 | B12: A2003 | C12: Character | D12: 1 | E12: 신용관리대상 및 당행정보관리 등재고객(KB 국민은행 정보) | F12: 내부항목 | G12: KB카드실시간KO IN ('014') | I12: GEA심사사전정보내역 | J12: 현재일자기준대출심사모형사전조회출력Dto | K12: 014 | L12: IF (불가사유코드_V3 = 014) THEN 0 ELSE 1 END
A13: =ROW()-1 -> 12 | B13: A2004 | C13: Character | D13: 1 | E13: NICE 타사연체정보 보유고객(신용정보) | F13: 내부항목 | G13: KB카드실시간KO IN ('118') | I13: GEA심사사전정보내역 | J13: 현재일자기준대출심사모형사전조회출력Dto | K13: 118 | L13: N/A
A14: =ROW()-1 -> 13 | B14: A2005 | C14: Character | D14: 1 | E14: KCB 타사연체정보 보유고객(신용정보) | F14: 내부항목 | G14: KB카드실시간KO IN ('012') | I14: GEA심사사전정보내역 | J14: 현재일자기준대출심사모형사전조회출력Dto | K14: 012 | L14: N/A
A15: =ROW()-1 -> 14 | B15: A2006 | C15: Character | D15: 1 | E15: 사망실종 고객(고객정보) | F15: 내부항목 | G15: KB카드실시간KO IN ('001') | I15: GEA심사사전정보내역 | J15: 현재일자기준대출심사모형사전조회출력Dto | K15: 001 | L15: N/A
A16: =ROW()-1 -> 15 | B16: A2007 | C16: Character | D16: 1 | E16: 거래주의보정보 등록고객(고객정보) | F16: 내부항목 | G16: KB카드실시간KO IN ('003') | I16: GEA심사사전정보내역 | J16: 현재일자기준대출심사모형사전조회출력Dto | K16: 003 | L16: N/A
A17: =ROW()-1 -> 16 | B17: A2008 | C17: Character | D17: 1 | E17: 워크아웃 등록고객 | F17: 내부항목 | G17: KB카드실시간KO IN ('005') | I17: GEA심사사전정보내역 | J17: 현재일자기준대출심사모형사전조회출력Dto | K17: 005 | L17: N/A
A18: =ROW()-1 -> 17 | B18: A2009 | C18: Character | D18: 1 | E18: 장기카드대출 연체고객 | F18: 내부항목 | G18: KB카드실시간KO IN ('008') | I18: GEA심사사전정보내역 | J18: 현재일자기준대출심사모형사전조회출력Dto | K18: 008 | L18: N/A
A19: =ROW()-1 -> 18 | B19: A2010 | C19: Character | D19: 1 | E19: 요주의 등록고객(신용정보) | F19: 내부항목 | G19: KB카드실시간KO IN ('009') | I19: GEA심사사전정보내역 | J19: 현재일자기준대출심사모형사전조회출력Dto | K19: 009 | L19: N/A
A20: =ROW()-1 -> 19 | B20: A2011 | C20: Character | D20: 1 | E20: 신용불량 채무관계제한 등록고객(신용정보) | F20: 내부항목 | G20: KB카드실시간KO IN ('010') | I20: GEA심사사전정보내역 | J20: 현재일자기준대출심사모형사전조회출력Dto | K20: 010 | L20: N/A
A21: =ROW()-1 -> 20 | B21: A2012 | C21: Character | D21: 1 | E21: 은행 사전채무조정 신청자 및 확정자 등록고객(KB 국민은행 정보) | F21: 내부항목 | G21: KB카드실시간KO IN ('015') | I21: GEA심사사전정보내역 | J21: 현재일자기준대출심사모형사전조회출력Dto | K21: 015 | L21: N/A
A22: =ROW()-1 -> 21 | B22: A2013 | C22: Character | D22: 1 | E22: 고객기본정보 구분코드 오류(고객정보) | F22: 내부항목 | G22: KB카드실시간KO IN ('016') | I22: GEA심사사전정보내역 | J22: 현재일자기준대출심사모형사전조회출력Dto | K22: 016 | L22: N/A
A23: =ROW()-1 -> 22 | B23: A2014 | C23: Numeric | D23: 15 | E23: 카드론대출잔액 | F23: 내부항목 | I23: GEA심사사전정보내역 | J23: 현재일자기준대출심사모형사전조회출력Dto | K23: 카드론대출잔액 | L23: N/A
A24: =ROW()-1 -> 23 | B24: A2015 | C24: Numeric | D24: 15 | E24: 오토론대출잔액 | F24: 내부항목 | I24: GEA심사사전정보내역 | J24: 현재일자기준대출심사모형사전조회출력Dto | K24: 오토론대출잔액 | L24: N/A
A25: =ROW()-1 -> 24 | B25: A2016 | C25: Numeric | D25: 15 | E25: 신용대출잔액 | F25: 내부항목 | I25: GEA심사사전정보내역 | J25: 현재일자기준대출심사모형사전조회출력Dto | K25: 신용대출잔액 | L25: N/A
A26: =ROW()-1 -> 25 | B26: A2017 | C26: Numeric | D26: 15 | E26: 대환론대출잔액 | F26: 내부항목 | I26: GEA심사사전정보내역 | J26: 현재일자기준대출심사모형사전조회출력Dto | K26: 대환론대출잔액 | L26: N/A
A27: =ROW()-1 -> 26 | B27: A2018 | C27: Numeric | D27: 15 | E27: 순수 비회원 신용대출 잔액 | F27: 내부항목 | G27: KHC 추가 필요 항목 | I27: GEA심사사전정보내역 | J27: 현재일자기준대출심사모형사전조회출력Dto | K27: 순수비회원신용대출잔액_N15 | L27: N/A
A28: =ROW()-1 -> 27 | B28: A2019 | C28: Numeric | D28: 15 | E28: 당사 신용카드 잔액 | F28: 내부항목 | I28: GEA심사사전정보내역 | J28: 현재일자기준대출심사모형사전조회출력Dto | K28: bd당사신용카드잔액 | L28: N/A
A29: =ROW()-1 -> 28 | B29: A2020 | C29: Character | D29: 1 | E29: 유효회원여부 | F29: 내부항목 | I29: GEA심사사전정보내역 | J29: 현재일자기준대출심사모형사전조회출력Dto | K29: KB카드유효회원여부 | L29: N/A
A30: =ROW()-1 -> 29 | B30: A2021 | C30: Character | D30: 1 | E30: 유효고객여부 | F30: 내부항목 | I30: GEA심사사전정보내역 | J30: 현재일자기준대출심사모형사전조회출력Dto | K30: KB카드유효고객여부 | L30: N/A
A31: =ROW()-1 -> 30 | B31: A2022 | C31: Character | D31: 1 | E31: 신용카드소지여부 | F31: 내부항목 | I31: GEA심사사전정보내역 | J31: 현재일자기준대출심사모형사전조회출력Dto | K31: 유효신용카드소지여부 | L31: N/A
A32: =ROW()-1 -> 31 | B32: A2023 | C32: Character | D32: 1 | E32: 체크카드보유여부 | F32: 내부항목 | I32: GEA심사사전정보내역 | J32: 현재일자기준대출심사모형사전조회출력Dto | K32: 유효체크카드소지여부 | L32: N/A
A33: =ROW()-1 -> 32 | B33: A2024 | C33: Character | D33: 1 | E33: 가맹점대표자여부 | F33: 내부항목 | I33: GEA심사사전정보내역 | J33: 현재일자기준대출심사모형사전조회출력Dto | K33: 가맹점대표자여부 | L33: N/A
A34: =ROW()-1 -> 33 | B34: A2025 | C34: Character | D34: 2 | E34: 가맹점주등급 | F34: 내부항목 | I34: GEA심사사전정보내역 | J34: 미정 | K34: 미정 | L34: N/A | P34: TOBE에 적용되지 않음 - TSMEDSB11(tobe에 카드심사업무에서 만들것임), VSTAFB036->THKBBGY21->TBGDBC001 (가맹점 이미영b)
A35: =ROW()-1 -> 34 | B35: A2026 | C35: Numeric | D35: 15 | E35: 최근 6개월 가맹점 매출액 | F35: 내부항목 | I35: GEA심사사전정보내역 | J35: 현재일자기준대출심사모형사전조회출력Dto | K35: 최근6개월가맹점매출금액 | L35: N/A | P35: TOBE에 적용되지 않음 - TSTAFTH08->TBGEAA216, VSTAFB036->THKBBGY21->TBGDBC001 (가맹점 이미영b)
A36: =ROW()-1 -> 35 | B36: A2027 | C36: Numeric | D36: 15 | E36: 당사 CA 잔액 | F36: 내부항목 | I36: GEA심사사전정보내역 | J36: 현재일자기준대출심사모형사전조회출력Dto | K36: bdCA잔액 | L36: N/A
A37: =ROW()-1 -> 36 | B37: A2028 | C37: Numeric | D37: 15 | E37: 당사 RLS이월잔액 | F37: 내부항목 | I37: GEA심사사전정보내역 | J37: 현재일자기준대출심사모형사전조회출력Dto | K37: RLS이월금액_N15 | L37: N/A
A38: =ROW()-1 -> 37 | B38: A2029 | C38: Numeric | D38: 15 | E38: 당사 RCA이월잔액 | F38: 내부항목 | I38: GEA심사사전정보내역 | J38: 현재일자기준대출심사모형사전조회출력Dto | K38: RCA이월금액_N15 | L38: N/A
A39: =ROW()-1 -> 38 | B39: A2030 | C39: Numeric | D39: 15 | E39: 매입할부금융잔액 | F39: 내부항목 | I39: GEA심사사전정보내역 | J39: 현재일자기준대출심사모형사전조회출력Dto | K39: 매입할부금융잔액_N15 | L39: N/A
A40: =ROW()-1 -> 39 | B40: A2031 | C40: Numeric | D40: 15 | E40: 부채증명서 발급 경과일수 (단위: 일) | F40: 내부항목 | I40: GEA심사사전정보내역 | J40: 현재일자기준대출심사모형사전조회출력Dto | K40: 부채증명서발급경과일수 | L40: N/A
...

Sheet RCLIPS수신(일사천리론)_최종
A1: < 중금리론(일사천리론) >
A2: * RCLIPS → 처리계
A3: NO | B3: 원천구분 | C3: R-Clips 코드 | D3: 항목명 | E3: 형식 | F3: 길이 | G3: 구분 | H3: 변경구분 | I3: 컬럼명 | J3: 비고(NEW) | K3: 비고(OLD)
A4: =ROW()-3 -> 1 | B4: RCLIPS | D4: 기준년월 | E4: String | O4: : 삭제
A5: =ROW()-3 -> 2 | B5: RCLIPS | D5: 접수번호 | E5: String | F5: 14 | O5: : 신규 추가
A6: =ROW()-3 -> 3 | B6: RCLIPS | D6: 고객식별자 | E6: String | F6: 10 | O6: : 변경
A7: =ROW()-3 -> 4 | B7: RCLIPS | D7: 회원일련번호 | E7: String | F7: 8
A8: =ROW()-3 -> 5 | B8: RCLIPS | D8: 결과코드 | E8: String | F8: 20 | G8: 결과코드 | J8: 0000이 아닐 경우 오류 | K8: 0000이 아닐 경우 오류 // 추가_20180917
A9: =ROW()-3 -> 6 | B9: RCLIPS | D9: 결과항목(코드5+값80) 반복 건수 | E9: Numeric | F9: 20 | G9: 결과건수 | J9: 신규추가 | K9: 신규추가 (코드5+값15) // 추가_20180917
A10: =ROW()-3 -> 7 | B10: RCLIPS | C10: R0001 | D10: 상품코드 | E10: C | F10: 15 | G10: 결과항목 | I10: 저장안함 | J10: [i카드론신청서접수번호신규조회E].[카드론평가상품구분코드] input값 저장, 카드론평가상품구분코드
A11: =ROW()-3 -> 8 | B11: RCLIPS | C11: R0002 | D11: 신청평점 | E11: N | F11: 15 | G11: 결과항목 | I11: 대출신청평점
A12: =ROW()-3 -> 9 | B12: RCLIPS | C12: R0003 | D12: 신청등급 | E12: N | F12: 15 | G12: 결과항목 | I12: 신청등급코드 s신청등급
A13: =ROW()-3 -> 10 | B13: RCLIPS | C13: R0004 | D13: 결합등급 | E13: N | F13: 15 | G13: 결과항목 | I13: 결합등급코드 s결합등급
A14: =ROW()-3 -> 11 | B14: RCLIPS | C14: R0005 | D14: 전략등급 | E14: C | F14: 15 | G14: 결과항목 | I14: 전략등급코드 | J14: 18번 12번 전략에 따라 자릿수 다름
A15: =ROW()-3 -> 12 | B15: RCLIPS | C15: R0006 | D15: Thin-file여부 | E15: N | F15: 15 | G15: 결과항목 | I15: 신용정보부족대상자여부
A16: =ROW()-3 -> 13 | B16: RCLIPS | C16: R0007 | D16: Knock-out여부 | E16: N | F16: 15 | G16: 결과항목 | I16: 낙아웃여부
A17: =ROW()-3 -> 14 | B17: RCLIPS | C17: R0008 | D17: 월소득 | E17: N | F17: 15 | G17: 결과항목 | I17: 월소득금액
A18: =ROW()-3 -> 15 | B18: RCLIPS | C18: R0009 | D18: DTI가중치 | E18: N | F18: 15 | G18: 결과항목 | I18: DTI계산율 | J18: 20190326 확인필요. 해당문서에는 삭제로 되어있으나, R클립스최신전문에 포함되어 있음 (차세대_Rclips_인터페이스_Online_C6_ASS_v0.4_20190129.xlsx) | K18: 삭제 요청
A19: =ROW()-3 -> 16 | B19: RCLIPS | C19: R0010 | D19: 월원리금상환금액 | E19: N | F19: 15 | G19: 결과항목 | I19: 월원리금상환금액
A20: =ROW()-3 -> 17 | B20: RCLIPS | C20: R0011 | D20: 월가처분소득 | E20: N | F20: 15 | G20: 결과항목 | I20: 월가처분소득금액
A21: =ROW()-3 -> 18 | B21: RCLIPS | C21: R0012 | D21: 적용금리 | E21: N | F21: 15 | G21: 결과항목 | I21: 적용이율
A22: =ROW()-3 -> 19 | B22: RCLIPS | C22: R0013 | D22: 적용금리코드 | E22: C | F22: 15 | G22: 결과항목 | I22: 카드론금리등급구분코드
A23: =ROW()-3 -> 20 | B23: RCLIPS | C23: R0014 | D23: 기초한도 | E23: N | F23: 15 | G23: 결과항목 | I23: RCLIPS초기한도금액
A24: =ROW()-3 -> 21 | B24: RCLIPS | C24: R0015 | D24: 신용한도CAP | E24: N | F24: 15 | G24: 결과항목 | I24: RCLIPS신용한도제한금액
A25: =ROW()-3 -> 22 | B25: RCLIPS | C25: R0016 | G25: 결과항목 | I25: CB등급한도제한금액
A26: =ROW()-3 -> 23 | B26: RCLIPS | C26: R0017 | D26: 연령한도CAP | E26: N | F26: 15 | G26: 결과항목 | I26: 연령한도제한금액
A27: =ROW()-3 -> 24 | B27: RCLIPS | C27: R0018 | D27: 신용한도 | E27: N | F27: 15 | G27: 결과항목 | I27: 신용한도금액
A28: =ROW()-3 -> 25 | B28: RCLIPS | C28: R0019 | D28: 시스템한도금액 | E28: N | F28: 15 | G28: 결과항목 | I28: RCLIPS신용한도금액
A29: =ROW()-3 -> 26 | B29: RCLIPS | C29: R0020 | D29: 대출가능금액 | E29: N | F29: 15 | G29: 결과항목 | I29: 대출가능금액
A30: =ROW()-3 -> 27 | B30: RCLIPS | C30: R0021 | D30: 한도충족률 | E30: N | F30: 15 | G30: 결과항목 | I30: 대출한도충족률 | J30: 20190326 확인필요. 해당문서에는 삭제로 되어있으나, R클립스최신전문에 포함되어 있음 (차세대_Rclips_인터페이스_Online_C6_ASS_v0.4_20190129.xlsx) | K30: 삭제 요청
A31: =ROW()-3 -> 28 | B31: RCLIPS | C31: R0022 | D31: 한도결과코드 | E31: C | F31: 15 | G31: 결과항목 | I31: 한도결과코드 | J31: 20190326 확인필요. 해당문서에는 삭제로 되어있으나, R클립스최신전문에 포함되어 있음 (차세대_Rclips_인터페이스_Online_C6_ASS_v0.4_20190129.xlsx) | K31: 삭제 요청
A32: =ROW()-3 -> 29 | B32: RCLIPS | C32: R0023 | D32: 시스템판정결과 | E32: C | F32: 15 | G32: 결과항목 | I32: 대출평가결과구분코드 s대출평가결과구분코드
A33: =ROW()-3 -> 30 | B33: RCLIPS | C33: R0024 | D33: 시스템상세판정코드 | E33: C | F33: 15 | G33: 결과항목 | I33: 시스템상세판정코드
A34: =ROW()-3 -> 31 | B34: RCLIPS | C34: R0025 | D34: 우대한도 | E34: N | F34: 15 | G34: 결과항목 | I34: 우대한도금액
A35: =ROW()-3 -> 32 | B35: RCLIPS | C35: R0026 | D35: DTI | E35: N | F35: 15 | G35: 결과항목 | I35: DTI월상환원금
A36: =ROW()-3 -> 33 | B36: RCLIPS | C36: R0027 | D36: 신용가중치 | E36: N | F36: 15 | G36: 결과항목 | I36: RCLIPS신용가중치율 | J36: 20190326 확인필요. 해당문서에는 삭제로 되어있으나, R클립스최신전문에 포함되어 있음 (차세대_Rclips_인터페이스_Online_C6_ASS_v0.4_20190129.xlsx) | K36: 삭제 요청
A37: =ROW()-3 -> 34 | B37: RCLIPS | C37: R0028 | D37: 대출가능개월수 | E37: N | F37: 15 | G37: 결과항목 | I37: 대출가능개월수
A38: =ROW()-3 -> 35 | B38: RCLIPS | C38: R0029 | D38: 거치가능개월수 | E38: N | F38: 15 | G38: 결과항목 | I38: 신청가능거치기간개월수
A39: =ROW()-3 -> 36 | B39: RCLIPS | C39: R0030 | D39: 우대대상여부 | E39: C | F39: 15 | G39: 결과항목 | I39: 제휴기관연계대출우대대상여부
A40: =ROW()-3 -> 37 | B40: RCLIPS | C40: R0031 | D40: 우대한도금액 | E40: N | F40: 15 | G40: 결과항목 | I40: 제휴기관연계대출우대한도금액
...

Sheet RCLIPS송신(개사)
A1: Seq | B1: RCLIPS코드 | C1: 속성 | D1: 길이 | E1: R클립스_항목명 | F1: 구분 | G1: R클립스_비고 | H1: 원천정보그룹 | I1: 원천정보(원본) | J1: MDD_호출CPBI/EBI | K1: MDD_항목명 | L1: CB사 항목코드 | M1: CB사 전문번호 | N1: BITMAP | O1: 변경구분 | P1: 비고2(개발팀) | Q1: 필수입력
A2: =ROW()-1 -> 1 | B2: PKG_ID | C2: String | D2: 20 | E2: Online_C9_ASS
A3: =ROW()-1 -> 2 | B3: CNT | C3: Numeric | D3: 3 | E3: 제공항목건수 | G3: 항목코드5+항목값15
A4: =ROW()-1 -> 3 | B4: A1001 | C4: S | D4: 8 | E4: 신청 일자
A5: =ROW()-1 -> 4 | B5: A1002 | C5: S | D5: 14 | E5: 신청서접수번호
A6: =ROW()-1 -> 5 | B6: A1003 | C6: S | D6: 8 | E6: 개업일 | F6: 제공항목 | H6: 내부정보 | I6: GEA심사사전정보내역 | J6: 심사사전정보내역조회C > 현재일자기준대출심사모형사전조회
A7: =ROW()-1 -> 6 | B7: A1004 | C7: L | D7: 15 | E7: 연령
A8: =ROW()-1 -> 7 | B8: A1005 | C8: S | D8: 1 | E8: 외국인여부
A9: =ROW()-1 -> 8 | B9: A1006 | C9: S | D9: 2 | E9: 상품코드
A10: =ROW()-1 -> 9 | B10: A1007 | C10: S | D10: 10 | E10: 사업자번호
A11: =ROW()-1 -> 10 | B11: A1008 | C11: S | D11: 2 | E11: 입력업종코드
A12: =ROW()-1 -> 11 | B12: A2001 | C12: S | D12: 1 | E12: 기업카드거래정지여부 | H12: 내부
A13: =ROW()-1 -> 12 | B13: A2002 | C13: S | D13: 1 | E13: 기업카드연체여부 | H13: 내부
A14: =ROW()-1 -> 13 | B14: A2003 | C14: S | D14: 1 | E14: 기업카드특수채권보유여부 | H14: 내부
A15: =ROW()-1 -> 14 | B15: A2005 | C15: S | D15: 1 | E15: 대표자개인카드연체여부 | H15: 내부
A16: =ROW()-1 -> 15 | B16: A2007 | C16: S | D16: 1 | E16: 대표자특수채권보유여부 | H16: 내부
A17: =ROW()-1 -> 16 | B17: A2008 | C17: S | D17: 1 | E17: GHA소매비소매구분 | H17: 내부
H18: 내부
A19: =ROW()-1 -> 18 | B19: A2004 | C19: S | D19: 1 | E19: 대표자개인카드거래정지여부 | H19: 내부(GHA)
A20: =ROW()-1 -> 19 | B20: A2009 | C20: L | D20: 15 | E20: GAF은행익스포져금액 | H20: 내부(MED→GAF→GEA)
A21: =ROW()-1 -> 20 | B21: A2010 | C21: L | D21: 15 | E21: GAF카드익스포져금액 | H21: 내부(MED→GAF→GEA)
A22: =ROW()-1 -> 21 | B22: A2011 | C22: S | D22: 2 | E22: GHA기업BS등급 | H22: 내부(GHA)
A23: =ROW()-1 -> 22 | B23: A2012 | C23: S | D23: 2 | E23: GHA그룹CRS등급 | H23: 내부(GHA)
A24: =ROW()-1 -> 23 | B24: A2014 | C24: S | D24: 2 | E24: 대표자스타클럽구분 | H24: 내부
A25: =ROW()-1 -> 24 | B25: A2015 | C25: S | D25: 1 | E25: 거래주의정보 등록고객 | H25: 내부
A26: =ROW()-1 -> 25 | B26: A2016 | C26: S | D26: 1 | E26: 워크아웃등록고객 | H26: 내부
A27: =ROW()-1 -> 26 | B27: A2006 | C27: S | D27: 1 | E27: 대표자장기카드대출연체여부 | H27: 내부
A28: =ROW()-1 -> 27 | B28: A2017 | C28: S | D28: 1 | E28: 요주의 등록고객 | H28: 내부
A29: =ROW()-1 -> 28 | B29: A2018 | C29: S | D29: 1 | E29: 신용불량채무관계제한등록고객 | H29: 내부
A30: =ROW()-1 -> 29 | B30: A2019 | C30: S | D30: 1 | E30: 고객기본정보 구분코드 오류 | H30: 내부
... A60: =ROW()-1 -> 59 | B60: A2049 | C60: L | D60: 15 | E60: 기업대출한도 | H60: 내부
A61: =ROW()-1 -> 60 | B61: A2050 | C61: L | D61: 15 | E61: 연소득금액(네이버_국세청) | H61: 입력값 | J61: i개인사업자대출RCLIPS전문조립C | K61: 연소득금액 | M61: / 12
A62: =ROW()-1 -> 61 | B62: A2051 | C62: L | D62: 15 | E62: 이지대환대출가능금액 | J62: 대출가능개월수월별원리금조회 | K62: bd이지대환대출가능금액
A63: =ROW()-1 -> 62 | B63: A2052 | C63: L | D63: 15 | E63: 이지대환대출잔액 | I63: r심사사전정보내역조회C | J63: 현재일자기준대출심사모형사전조회출력Dto | K63: 이지대환대출잔액_N15
A64: =ROW()-1 -> 63 | B64: A2053 | C64: S | D64: 1 | E64: 우대대상여부 | J64: rGEA우대프랜차이즈대상여부조회E | K64: 우대프랜차이즈대상여부_V1
A65: =ROW()-1 -> 64 | B65: A2054 | C65: S | D65: 2 | E65: 채널구분 | J65: 입력COMDtoctx | K65: SDT채널구분코드
A66: =ROW()-1 -> 65 | B66: A2055 | C66: S | D66: 2 | E66: 채널세부구분 | J66: 입력COMDtoctx | K66: SDT채널세부업무구분코드
A67: =ROW()-1 -> 66 | B67: A2056 | C67: N | D67: 9 | E67: 스크래핑소득_국민연금환산 | J67: r스크래핑국민연금최종소득금액조회E | K67: 스크래핑국민연금최종소득금액_N15
A68: =ROW()-1 -> 67 | B68: A2057 | C68: N | D68: 9 | E68: 스크래핑소득_공무원연금환산 | J68: r스크래핑공무원연금최종소득금액조회E | K68: 스크래핑공무원연금최종소득금액_N15
A69: =ROW()-1 -> 68 | B69: A2058 | C69: N | D69: 9 | E69: 카드론사전한도 | K69: bd카드론최고금액 | M69: tbgeaa209 Max값
...

Sheet RCLIPS수신(개사)
A1: NO | B1: 원천구분 | C1: R-Clips 코드 | D1: 항목명 | E1: 형식 | F1: 길이 | G1: 구분 | H1: TBGEAA218,MDD 항목명 | I1: 변경구분 | J1: 비고(현업) | K1: 비고(NEW) | L1: 비고(OLD)
A2: =ROW()-3 -> -1 | B2: RCLIPS | D2: 결과코드 | E2: String | F2: 4 | J2: 0000이 아닐 경우 오류
A3: =ROW()-3 -> 0 | B3: RCLIPS | D3: 결과건수 | E3: Numeric | F3: 3 | J3: 결과항목(코드5+값15) 건수
A4: =ROW()-3 -> 1 | B4: RCLIPS | D4: 기준년월 | E4: String | F4: 6
A5: =ROW()-3 -> 2 | B5: RCLIPS | D5: 접수번호 | E5: String | F5: 14
A6: =ROW()-3 -> 3 | B6: RCLIPS | D6: 고객식별자 | E6: String | F6: 10
A7: =ROW()-3 -> 4 | B7: RCLIPS | D7: 회원일련번호 | E7: String | F7: 8
A8: =ROW()-3 -> 5 | B8: RCLIPS | C8: A1002 | D8: 신청서접수번호 | E8: S | F8: 14 | G8: 입력항목 | H8: 카드론신청서접수번호
A9: =ROW()-3 -> 6 | B9: RCLIPS | C9: A4003 | D9: NICE_최종연소득금액 | E9: L | F9: 15 | G9: 입력항목 | H9: NICE추정소득금액
A10: =ROW()-3 -> 7 | B10: RCLIPS | C10: A4005 | D10: 연간원리금상환추정금액 | E10: L | F10: 15 | G10: 입력항목 | H10: 연간원리금상환금액
A11: =ROW()-3 -> 8 | B11: RCLIPS | C11: A4229 | D11: NICE신용평점 | E11: L | F11: 15 | G11: 입력항목 | H11: 실시간NICE신용평점
A12: =ROW()-3 -> 9 | B12: RCLIPS | C12: A6010 | D12: KCB추정소득 | E12: L | F12: 15 | G12: 입력항목 | H12: KCB추정소득금액
A13: =ROW()-3 -> 10 | B13: RCLIPS | C13: A6272 | D13: KCB신용등급 | E13: S | F13: 2 | G13: 입력항목 | H13: sKCB신용등급구분코드
A14: =ROW()-3 -> 11 | B14: RCLIPS | C14: A7010 | D14: GAF가맹점특화머신러닝평점 | E14: L | F14: 15 | G14: 입력항목 | H14: 가맹점특화머신러닝평점
A15: 6 | B15: RCLIPS | C15: R0001 | D15: 기업결합등급 | E15: S | F15: 2 | G15: 결과항목 | H15: 개인사업자CB결합등급구분코드 s결합등급
A16: 7 | B16: RCLIPS | C16: R0002 | D16: 기업AS평점 | E16: L | F16: 15 | G16: 결과항목 | H16: 소호ASS평점
A17: 8 | B17: RCLIPS | C17: R0003 | D17: 기업AS등급 | E17: S | F17: 2 | G17: 결과항목 | H17: 소호ASS등급 i컷오프신청등급 s소호ASS등급
A18: 9 | B18: RCLIPS | C18: R0004 | D18: 최저CBML등급 | E18: S | F18: 2 | G18: 결과항목 | H18: 최저CB등급구분코드
A19: 10 | B19: RCLIPS | C19: R0005 | D19: 소호특화통합평점 | E19: L | F19: 15 | G19: 결과항목 | H19: 소호특화통합평가점수
A20: 11 | B20: RCLIPS | C20: R0006 | D20: 소호특화통합등급 | E20: S | F20: 2 | G20: 결과항목 | H20: 소호특화등급구분코드 s소호특화등급코드
A21: 12 | B21: RCLIPS | C21: R0007 | D21: 통합소호등급 | E21: S | F21: 2 | G21: 결과항목 | H21: 소호BSS등급구분코드
A22: 13 | B22: RCLIPS | C22: R0008 | D22: 최종한도 | E22: L | F22: 15 | G22: 결과항목 | H22: 실시간최종한도금액
A23: 14 | B23: RCLIPS | C23: R0009 | D23: 최장대출기간 | E23: L | F23: 15 | G23: 결과항목 | H23: 실시간최장대출기간수
A24: 15 | B24: RCLIPS | C24: R0010 | D24: 최장거치기간 | E24: L | F24: 15 | G24: 결과항목 | H24: 실시간최장거치기간수
A25: 16 | B25: RCLIPS | C25: R0011 | D25: 초기한도 | E25: L | F25: 15 | G25: 결과항목 | H25: RCLIPS초기한도금액
A26: 17 | B26: RCLIPS | C26: R0012 | D26: N1차조정후한도 | E26: L | F26: 15 | G26: 결과항목 | H26: N1차조정후한도금액
... A54: 45 | B54: RCLIPS | C54: R0040 | D54: 소매비소매구분제한여부 | E54: S | F54: 1 | G54: 결과항목 | H54: 소매비소매구분제한여부
A55: 46 | B55: RCLIPS | C55: R0041 | D55: 내부정책발급제한내용 | E55: S | F55: 200 | G55: 결과항목 | H55: 내부정책발급제한내용
A56: 47 | B56: RCLIPS | C56: R0042 | D56: 사업장발급제한내용 | E56: S | F56: 200 | G56: 결과항목 | H56: 사업장발급제한내용
A57: 48 | B57: RCLIPS | C57: R0043 | D57: 대표자발급제한내용 | E57: S | F57: 200 | G57: 결과항목 | H57: 대표자발급제한내용
A58: 49 | B58: RCLIPS | C58: R0044 | D58: 최종KO결과코드 | E58: S | F58: 200 | G58: 결과항목 | H58: 최종불가사유결과내용
A59: 46 | B59: RCLIPS | C59: R0045 | D59: 적용금리코드 | E59: S | F59: 2 | G59: 결과항목 | H59: 카드론금리등급구분코드
A60: 47 | B60: RCLIPS | C60: R0046 | D60: 적용금리 | E60: D | F60: 5.2 | G60: 결과항목 | H60: 최종대출적용금리
A61: 48 | B61: RCLIPS | C61: R0047 | D61: 대표자KCBDSR비율 | E61: D | F61: 5.2 | G61: 결과항목 | H61: 대표자KCBDSR비율
A62: 49 | B62: RCLIPS | C62: R0048 | D62: 대표자소득금액 | E62: L | F62: 15 | G62: 결과항목 | H62: 대표자소득금액
A63: 50 | B63: RCLIPS | C63: R0049 | D63: N4차조정후한도 | E63: L | F63: 15 | G63: 결과항목 | H63: N4차조정후한도금액
A64: 51 | B64: RCLIPS | C64: R0050 | D64: 최종시스템판정결과 | E64: S | F64: 2 | G64: 결과항목 | H64: 대출평가결과구분코드 s대출평가결과구분코드
A65: 52 | B65: RCLIPS | C65: R0051 | D65: Rclips버젼 | E65: S | F65: 2 | G65: 결과항목 | H65: 저장안함
A66: 53 | B66: RCLIPS | C66: R0052 | D66: KBGS중위세분화CBonly등급 | E66: S | F66: 2 | G66: 결과항목 | H66: 저장안함
A67: 54 | B67: RCLIPS | C67: R0053 | D67: KBGS중위세분화신용등급 | E67: S | F67: 2 | G67: 결과항목 | H67: 저장안함
...

Sheet RCLIPS송신(대환)
A1: Seq | B1: RCLIPS코드 | C1: 속성 | D1: 길이 | E1: R클립스_항목명 | F1: 구분 | G1: R클립스_비고 | H1: 원천정보그룹 | I1: 원천정보(원본) | J1: MDD_호출CPBI/EBI | K1: MDD_항목명 | L1: CB사 항목코드 | M1: CB사 전문번호 | N1: BITMAP | O1: 변경구분 | P1: 비고2(개발팀) | Q1: 필수입력
A2: =ROW()-1 -> 1 | B2: PKG_ID | C2: String | D2: 20 | E2: Online_C9_ASS
A3: =ROW()-1 -> 2 | B3: CNT | C3: Numeric | D3: 3 | E3: 제공항목건수 | G3: 항목코드5+항목값15
A4: =ROW()-1 -> 3 | B4: A1000 | C4: String | D4: 14 | E4: 접수번호 | G4: 신용대출(C6_A1006)와동일
A5: =ROW()-1 -> 4 | B5: A1001 | C5: String | D5: 2 | E5: 상품코드
A6: =ROW()-1 -> 5 | B6: A1004 | C6: Long | D6: 15 | E6: 연령 | G6: 신용대출(C6_A1004)와동일
A7: =ROW()-1 -> 6 | B7: A1005 | C7: String | D7: 1 | E7: 외국인여부 | G7: 신용대출(C6_A1005)와동일
A8: =ROW()-1 -> 7 | B8: A2001 | C8: String | D8: 1 | E8: 여신연체고객(KB 국민은행정보) | G8: 신용대출(C6_A2001)와동일 | I8: GEA심사사전정보내역 | J8: 심사사전정보내역조회C > 현재일자기준대출심사모형사전조회 | K8: IF (불가사유코드_V3 = 103) THEN 0 ELSE 1 END
A9: =ROW()-1 -> 8 | B9: A2002 | C9: String | D9: 1 | E9: 신용카드 거래정지 등록고객 | G9: 신용대출(C6_A2002)와동일/C11_A2004와다름 | I9: GEA심사사전정보내역 | J9: 심사사전정보내역조회C > 현재일자기준대출심사모형사전조회 | K9: IF (불가사유코드_V3 = 006) THEN 0 ELSE 1 END
A10: =ROW()-1 -> 9 | B10: A2003 | C10: String | D10: 1 | E10: 신용관리대상 및 당행정보관리 등재고객(KB 국민은행 정보) | G10: 신용대출(C6_A2003)와동일 | I10: GEA심사사전정보내역 | J10: 심사사전정보내역조회C > 현재일자기준대출심사모형사전조회 | K10: IF (불가사유코드_V3 = 014) THEN 0 ELSE 1 END
